Workbook
Name GV_list: #REF!
Name responses_std: 'Nộp báo cáo'!$A$3:$G$2670
Name std_list: #REF!
Name Std_responses: 'Nộp báo cáo'!$A$3:$L$2670

Sheet Sheet1
A1: THỐNG KÊ NGÂN HÀNG CÂU HỎI KIẾN TẬP
A2: STT | B2: Nhà máy | C2: Số lượng câu hỏi hiện có | F2: Xin bổ sung
C3: Tổng quan nhà máy | D3: Quy trình, công nghệ | E3: Điều kiện ATTP | F3: Tổng quan nhà máy | G3: Quy trình, công nghệ | H3: Điều kiện ATTP
A4: 1 | B4: Yakult
A5: 2 | B5: Kewpie
A6: 3 | B6: Ajinomoto Biên Hòa
A7: 4 | B7: Ajinomoto Long Thành
A8: 5 | B8: Heineken
A9: 6 | B9: Nutifood
A10: 7
A11: 8
A12: 9
G15: =30*0.75*100*3 -> 6750

Sheet Tổng 24-25
A4: DANH SÁCH SINH VIÊN KHÓA 13 THỰC HIỆN HỌC PHẦN KIẾN TẬP Năm học 2024-2025
A6: STT | B6: Mã HS-SV | C6: Họ đệm | D6: Tên | E6: Ngày sinh | F6: Lớp học | G6: GVHD | H6: Số nhà máy TQ offline do khoa tổ chức | I6: Số lần nộp báo cáo | J6: Ghi chú
A7: 1 | B7: 2022220050 | C7: Huỳnh Dĩ | D7: An | E7: 01/03/2004 | F7: 13DHDB01 | G7: Trần Chí Hải | H7: =VLOOKUP(B7,'Dữ liệu TQNM'!$B$7:$F$769,5,0) -> 3 | I7: =COUNTIF('Nộp báo cáo'!$A$3:$A$1993,'Tổng 24-25'!B7) -> 3
A8: 2 | B8: 2022220068 | C8: Nguyễn Xuân | D8: An | E8: 28/07/2004 | F8: 13DHDB01 | G8: Trần Chí Hải | H8: =VLOOKUP(B8,'Dữ liệu TQNM'!$B$7:$F$769,5,0) -> 3 | I8: =COUNTIF('Nộp báo cáo'!$A$3:$A$1993,'Tổng 24-25'!B8) -> 3
A9: 3 | B9: 2022220181 | C9: Lê Thị Vân | D9: Anh | E9: 11/01/2004 | F9: 13DHDB01 | G9: Trần Chí Hải | H9: =VLOOKUP(B9,'Dữ liệu TQNM'!$B$7:$F$769,5,0) -> 2 | I9: =COUNTIF('Nộp báo cáo'!$A$3:$A$1993,'Tổng 24-25'!B9) -> 3
A10: 4 | B10: 2022220211 | C10: Nguyễn Đức Phương | D10: Anh | E10: 20/11/1999 | F10: 13DHDB01 | G10: Trần Chí Hải | H10: =VLOOKUP(B10,'Dữ liệu TQNM'!$B$7:$F$769,5,0) -> 3 | I10: =COUNTIF('Nộp báo cáo'!$A$3:$A$1993,'Tổng 24-25'!B10) -> 3
A11: 5 | B11: 2022220170 | C11: Phạm Tuấn | D11: Anh | E11: 25/09/2004 | F11: 13DHDB01 | G11: Trần Chí Hải | H11: =VLOOKUP(B11,'Dữ liệu TQNM'!$B$7:$F$769,5,0) -> 3 | I11: =COUNTIF('Nộp báo cáo'!$A$3:$A$1993,'Tổng 24-25'!B11) -> 3
A12: 6 | B12: 2022220182 | C12: Võ Trâm | D12: Anh | E12: 07/11/2004 | F12: 13DHDB01 | G12: Trần Chí Hải | H12: =VLOOKUP(B12,'Dữ liệu TQNM'!$B$7:$F$769,5,0) -> 3 | I12: =COUNTIF('Nộp báo cáo'!$A$3:$A$1993,'Tổng 24-25'!B12) -> 3
A13: 7 | B13: 2022220199 | C13: Phan Thị Mộng | D13: Anh | E13: 08/09/2004 | F13: 13DHDB01 | G13: Trần Chí Hải | H13: =VLOOKUP(B13,'Dữ liệu TQNM'!$B$7:$F$769,5,0) -> 2 | I13: =COUNTIF('Nộp báo cáo'!$A$3:$A$1993,'Tổng 24-25'!B13) -> 4
A14: 8 | B14: 2022220464 | C14: Nguyễn Chí | D14: Cường | E14: 26/10/2003 | F14: 13DHDB01 | G14: Trần Chí Hải | H14: =VLOOKUP(B14,'Dữ liệu TQNM'!$B$7:$F$769,5,0) -> 2 | I14: =COUNTIF('Nộp báo cáo'!$A$3:$A$1993,'Tổng 24-25'!B14) -> 3
A15: 9 | B15: 2022220619 | C15: Trần Thị Ngọc | D15: Diệu | E15: 06/10/2004 | F15: 13DHDB01 | G15: Trần Chí Hải | H15: =VLOOKUP(B15,'Dữ liệu TQNM'!$B$7:$F$769,5,0) -> 2 | I15: =COUNTIF('Nộp báo cáo'!$A$3:$A$1993,'Tổng 24-25'!B15) -> 3
A16: 10 | B16: 2022220980 | C16: Lê Cung | D16: Đỉnh | E16: 18/02/2004 | F16: 13DHDB01 | G16: Trần Chí Hải | H16: =VLOOKUP(B16,'Dữ liệu TQNM'!$B$7:$F$769,5,0) -> 3 | I16: =COUNTIF('Nộp báo cáo'!$A$3:$A$1993,'Tổng 24-25'!B16) -> 3
A17: 11 | B17: 2022221018 | C17: Trịnh Minh | D17: Đức | E17: 26/04/2004 | F17: 13DHDB01 | G17: Trần Chí Hải | H17: =VLOOKUP(B17,'Dữ liệu TQNM'!$B$7:$F$769,5,0) -> 3 | I17: =COUNTIF('Nộp báo cáo'!$A$3:$A$1993,'Tổng 24-25'!B17) -> 3
A18: 12 | B18: 2022220692 | C18: Trần Trí | D18: Dũng | E18: 07/04/2004 | F18: 13DHDB01 | G18: Trần Chí Hải | H18: =VLOOKUP(B18,'Dữ liệu TQNM'!$B$7:$F$769,5,0) -> 3 | I18: =COUNTIF('Nộp báo cáo'!$A$3:$A$1993,'Tổng 24-25'!B18) -> 2
... A95: 89 | B95: 2022222714 | C95: Nguyễn Thị Diễm | D95: My | E95: 19/11/2004 | F95: 13DHDB02 | G95: Ngô Duy Anh Triết | H95: =VLOOKUP(B95,'Dữ liệu TQNM'!$B$7:$F$769,5,0) -> 2 | I95: =COUNTIF('Nộp báo cáo'!$A$3:$A$1993,'Tổng 24-25'!B95) -> 2
A96: 90 | B96: 2022222797 | C96: Hồ Nhứt | D96: Nam | E96: 24/01/2004 | F96: 13DHDB02 | G96: Ngô Duy Anh Triết | H96: =VLOOKUP(B96,'Dữ liệu TQNM'!$B$7:$F$769,5,0) -> 1 | I96: =COUNTIF('Nộp báo cáo'!$A$3:$A$1993,'Tổng 24-25'!B96) -> 2 | J96: nhà máy Heineken, có ký tên nhưng không có làm bài ktra
A97: 91 | B97: 2022222953 | C97: Phạm Thị Thanh | D97: Ngân | E97: 25/05/2004 | F97: 13DHDB02 | G97: Ngô Duy Anh Triết | H97: =VLOOKUP(B97,'Dữ liệu TQNM'!$B$7:$F$769,5,0) -> 2 | I97: =COUNTIF('Nộp báo cáo'!$A$3:$A$1993,'Tổng 24-25'!B97) -> 3
A98: 92 | B98: 2022222939 | C98: Trịnh Thị Kim | D98: Ngân | E98: 02/10/2004 | F98: 13DHDB02 | G98: Ngô Duy Anh Triết | H98: =VLOOKUP(B98,'Dữ liệu TQNM'!$B$7:$F$769,5,0) -> 3 | I98: =COUNTIF('Nộp báo cáo'!$A$3:$A$1993,'Tổng 24-25'!B98) -> 2
A99: 93 | B99: 2022222938 | C99: Võ Thanh | D99: Ngân | E99: 30/03/2004 | F99: 13DHDB02 | G99: Ngô Duy Anh Triết | H99: =VLOOKUP(B99,'Dữ liệu TQNM'!$B$7:$F$769,5,0) -> 2 | I99: =COUNTIF('Nộp báo cáo'!$A$3:$A$1993,'Tổng 24-25'!B99) -> 3
A100: 94 | B100: 2022222946 | C100: Phan Thị Thúy | D100: Ngân | E100: 26/05/2004 | F100: 13DHDB02 | G100: Ngô Duy Anh Triết | H100: =VLOOKUP(B100,'Dữ liệu TQNM'!$B$7:$F$769,5,0) -> 3 | I100: =COUNTIF('Nộp báo cáo'!$A$3:$A$1993,'Tổng 24-25'!B100) -> 3
A101: 95 | B101: 2022223005 | C101: Phan Gia | D101: Nghi | E101: 27/09/2004 | F101: 13DHDB02 | G101: Ngô Duy Anh Triết | H101: =VLOOKUP(B101,'Dữ liệu TQNM'!$B$7:$F$769,5,0) -> 2 | I101: =COUNTIF('Nộp báo cáo'!$A$3:$A$1993,'Tổng 24-25'!B101) -> 3
A102: 96 | B102: 2022223112 | C102: Vũ Hà Hải | D102: Ngọc | E102: 14/12/2004 | F102: 13DHDB02 | G102: Ngô Duy Anh Triết | H102: =VLOOKUP(B102,'Dữ liệu TQNM'!$B$7:$F$769,5,0) -> 3 | I102: =COUNTIF('Nộp báo cáo'!$A$3:$A$1993,'Tổng 24-25'!B102) -> 3
A103: 97 | B103: 2022223160 | C103: Nguyễn Thành | D103: Nguyên | E103: 08/04/2004 | F103: 13DHDB02 | G103: Ngô Duy Anh Triết | H103: =VLOOKUP(B103,'Dữ liệu TQNM'!$B$7:$F$769,5,0) -> 2 | I103: =COUNTIF('Nộp báo cáo'!$A$3:$A$1993,'Tổng 24-25'!B103) -> 3
A104: 98 | B104: 2022222805 | C104: Võ Văn | D104: Ninh | E104: 04/07/2004 | F104: 13DHDB02 | G104: Ngô Duy Anh Triết | H104: =VLOOKUP(B104,'Dữ liệu TQNM'!$B$7:$F$769,5,0) -> 2 | I104: =COUNTIF('Nộp báo cáo'!$A$3:$A$1993,'Tổng 24-25'!B104) -> 3
A105: 99 | B105: 2022223699 | C105: Phạm Toàn | D105: Phú | E105: 01/09/2004 | F105: 13DHDB02 | G105: Ngô Duy Anh Triết | H105: =VLOOKUP(B105,'Dữ liệu TQNM'!$B$7:$F$769,5,0) -> 2 | I105: =COUNTIF('Nộp báo cáo'!$A$3:$A$1993,'Tổng 24-25'!B105) -> 3
A106: 100 | B106: 2022223878 | C106: Nguyễn Hoàng Kim | D106: Phương | E106: 09/06/2004 | F106: 13DHDB02 | G106: Ngô Duy Anh Triết | H106: =VLOOKUP(B106,'Dữ liệu TQNM'!$B$7:$F$769,5,0) -> 2 | I106: =COUNTIF('Nộp báo cáo'!$A$3:$A$1993,'Tổng 24-25'!B106) -> 4
A107: 101 | B107: 2022223860 | C107: Lê Thanh | D107: Phương | E107: 12/12/2004 | F107: 13DHDB02 | G107: Ngô Duy Anh Triết | H107: =VLOOKUP(B107,'Dữ liệu TQNM'!$B$7:$F$769,5,0) -> 2 | I107: =COUNTIF('Nộp báo cáo'!$A$3:$A$1993,'Tổng 24-25'!B107) -> 2
A108: 102 | B108: 2022223903 | C108: Mang Thị Kim | D108: Phượng | E108: 28/09/2004 | F108: 13DHDB02 | G108: Ngô Duy Anh Triết | H108: =VLOOKUP(B108,'Dữ liệu TQNM'!$B$7:$F$769,5,0) -> 2 | I108: =COUNTIF('Nộp báo cáo'!$A$3:$A$1993,'Tổng 24-25'!B108) -> 3
... A506: 500 | B506: 2005225854 | C506: Ngô Văn Quốc | D506: Việt | E506: 11/05/2004 | F506: 13DHTP02 | G506: Nguyễn Bảo Toàn | H506: =VLOOKUP(B506,'Dữ liệu TQNM'!$B$7:$F$769,5,0) -> 2 | I506: =COUNTIF('Nộp báo cáo'!$A$3:$A$1993,'Tổng 24-25'!B506) -> 3
A507: 501 | B507: 2005225981 | C507: Tạ Nhật Đan | D507: Vy | E507: 25/12/2004 | F507: 13DHTP02 | G507: Nguyễn Bảo Toàn | H507: =VLOOKUP(B507,'Dữ liệu TQNM'!$B$7:$F$769,5,0) -> 0 | I507: =COUNTIF('Nộp báo cáo'!$A$3:$A$1993,'Tổng 24-25'!B507) -> 2 | J507: 2 nhà máy tham quan tự do
A508: 502 | B508: 2005226113 | C508: Trần Thị | D508: Yến | E508: 09/08/2004 | F508: 13DHTP02 | G508: Nguyễn Bảo Toàn | H508: =VLOOKUP(B508,'Dữ liệu TQNM'!$B$7:$F$769,5,0) -> 2 | I508: =COUNTIF('Nộp báo cáo'!$A$3:$A$1993,'Tổng 24-25'!B508) -> 3
A509: 503 | B509: 2005220274 | C509: Trần Quỳnh Bảo | D509: Ân | E509: 25/09/2004 | F509: 13DHTP03 | G509: Nguyễn Bảo Toàn | H509: =VLOOKUP(B509,'Dữ liệu TQNM'!$B$7:$F$769,5,0) -> 2 | I509: =COUNTIF('Nộp báo cáo'!$A$3:$A$1993,'Tổng 24-25'!B509) -> 2
A510: 504 | B510: 2005220171 | C510: Trần Hoàng | D510: Anh | E510: 17/10/2004 | F510: 13DHTP03 | G510: Nguyễn Bảo Toàn | H510: =VLOOKUP(B510,'Dữ liệu TQNM'!$B$7:$F$769,5,0) -> 3 | I510: =COUNTIF('Nộp báo cáo'!$A$3:$A$1993,'Tổng 24-25'!B510) -> 2
A511: 505 | B511: 2005220253 | C511: Lê Thị Ngọc | D511: Ánh | E511: 25/09/2004 | F511: 13DHTP03 | G511: Hoàng Thị Ngọc Nhơn | H511: =VLOOKUP(B511,'Dữ liệu TQNM'!$B$7:$F$769,5,0) -> 3 | I511: =COUNTIF('Nộp báo cáo'!$A$3:$A$1993,'Tổng 24-25'!B511) -> 3
A512: 506 | B512: 2005220300 | C512: Nguyễn Gia | D512: Bảo | E512: 30/04/2004 | F512: 13DHTP03 | G512: Hoàng Thị Ngọc Nhơn | H512: =VLOOKUP(B512,'Dữ liệu TQNM'!$B$7:$F$769,5,0) -> 3 | I512: =COUNTIF('Nộp báo cáo'!$A$3:$A$1993,'Tổng 24-25'!B512) -> 2
A513: 507 | B513: 2005220449 | C513: Nguyễn Chí | D513: Cường | E513: 25/04/2004 | F513: 13DHTP03 | G513: Hoàng Thị Ngọc Nhơn | H513: =VLOOKUP(B513,'Dữ liệu TQNM'!$B$7:$F$769,5,0) -> 2 | I513: =COUNTIF('Nộp báo cáo'!$A$3:$A$1993,'Tổng 24-25'!B513) -> 0
A514: 508 | B514: 2005220881 | C514: Trần Đình | D514: Đạt | E514: 19/10/2004 | F514: 13DHTP03 | G514: Hoàng Thị Ngọc Nhơn | H514: =VLOOKUP(B514,'Dữ liệu TQNM'!$B$7:$F$769,5,0) -> 2 | I514: =COUNTIF('Nộp báo cáo'!$A$3:$A$1993,'Tổng 24-25'!B514) -> 2
A515: 509 | B515: 2005220627 | C515: Quách Quân | D515: Doanh | E515: 10/07/2004 | F515: 13DHTP03 | G515: Hoàng Thị Ngọc Nhơn | H515: =VLOOKUP(B515,'Dữ liệu TQNM'!$B$7:$F$769,5,0) -> 2 | I515: =COUNTIF('Nộp báo cáo'!$A$3:$A$1993,'Tổng 24-25'!B515) -> 3
A516: 510 | B516: 2005220628 | C516: Hồ Phùng Thanh | D516: Doanh | E516: 18/02/2004 | F516: 13DHTP03 | G516: Hoàng Thị Ngọc Nhơn | H516: =VLOOKUP(B516,'Dữ liệu TQNM'!$B$7:$F$769,5,0) -> 3 | I516: =COUNTIF('Nộp báo cáo'!$A$3:$A$1993,'Tổng 24-25'!B516) -> 3
A517: 511 | B517: 2005220823 | C517: Nguyễn Thùy | D517: Dương | E517: 10/05/2004 | F517: 13DHTP03 | G517: Hoàng Thị Ngọc Nhơn | H517: =VLOOKUP(B517,'Dữ liệu TQNM'!$B$7:$F$769,5,0) -> 3 | I517: =COUNTIF('Nộp báo cáo'!$A$3:$A$1993,'Tổng 24-25'!B517) -> 0
...

Sheet Dữ liệu TQNM
A2: TỔNG HỢP TÌNH HÌNH SINH VIÊN THAM QUAN NHÀ MÁY
A4: STT | B4: MSSV | C4: HỌ VÀ TÊN | E4: LỚP | F4: SỐ LƯỢNG | G4: NHÀ MÁY THAM QUAN 1 | L4: NHÀ MÁY THAM QUAN 2 | Q4: NHÀ MÁY THAM QUAN 3 | V4: NHÀ MÁY THAM QUAN 4 | AA4: NHÀ MÁY THAM QUAN 5
G5: TÊN | H5: THỜI GIAN | I5: HÌNH THỨC | J5: ĐIỂM | K5: ĐIỂM CỘNG | L5: TÊN | M5: THỜI GIAN | N5: HÌNH THỨC | O5: ĐIỂM | P5: ĐIỂM CỘNG | Q5: TÊN | R5: THỜI GIAN | S5: HÌNH THỨC | T5: ĐIỂM | U5: ĐIỂM CỘNG | V5: TÊN | W5: THỜI GIAN | X5: HÌNH THỨC | Y5: ĐIỂM | Z5: ĐIỂM CỘNG | AA5: TÊN | AB5: THỜI GIAN | AC5: HÌNH THỨC | AD5: ĐIỂM | AE5: ĐIỂM CỘNG
A6: (1) | B6: (2) | C6: (3) | D6: (4) | E6: (5) | F6: (6) | G6: (7) | L6: (8) | Q6: (9) | V6: (10) | AA6: (10)
A7: 1 | B7: 2005190573 | C7: Nguyễn Trọng | D7: Tài | E7: 10DHTP06
A8: 2 | B8: 2005200613 | C8: Phạm Minh | D8: Phương | E8: 11DHTP01 | F8: 2 | G8: Kewpie | H8: 45440 | I8: Offline | J8: 5 | L8: Acecook | M8: 45443 | N8: Offline | O8: 4.5
A9: 3 | B9: 2005201064 | C9: Trần Mai | D9: Thi | E9: 11DHTP01 | F9: 2 | G9: Kewpie | H9: 45398 | I9: Offline | J9: 8 | L9: Acecook | M9: 45399 | N9: Offline | O9: 5.5
A10: 4 | B10: 2005200682 | C10: Phạm Thị Bích | D10: Vân | E10: 11DHTP02 | F10: 4 | G10: Yakult | H10: 45629 | I10: Offline | J10: 7 | L10: Acecook | M10: 45721 | N10: Offline | O10: 2.5 | Q10: Acecook | R10: 45784 | S10: Offline | T10: 5.5 | V10: Yakult | W10: 45786 | X10: Offline | Y10: 6
A11: 5 | B11: 2005200495 | C11: Trần Phúc | D11: Hậu | E11: 11DHTP05 | F11: 1 | G11: Yakult | H11: 45817 | I11: Offline | J11: 6.5
A12: 6 | B12: 2005200237 | C12: Nguyễn Quốc | D12: Huy | E12: 11DHTP05 | F12: 1 | G12: Kewpie | H12: 45559 | I12: Offline | J12: 6.5
A13: 7 | B13: 2005200493 | C13: Trần Thị Mỹ | D13: Hạnh | E13: 11DHTP06 | F13: 3 | G13: Satori | H13: 45629 | I13: Offline | J13: 6 | L13: Kewpie | M13: 45636 | N13: Offline | O13: 4 | Q13: Acecook | R13: 45744 | S13: Offline | T13: 4.5
A14: 8 | B14: 2005202114 | C14: Nguyễn Tấn | D14: Phát | E14: 11DHTP09 | F14: 3 | G14: Kewpie | H14: 45589 | I14: Offline | J14: 7 | L14: Yakult | M14: 45602 | N14: Offline | O14: 5 | Q14: Acecook | R14: 45631 | S14: Offline | T14: 6
A15: 9 | B15: 2005208587 | C15: Nguyễn Đình | D15: Tân | E15: 11DHTP12 | F15: 1 | G15: Kewpie | H15: 45559 | I15: Offline | J15: 7.5
A16: 10 | B16: 2005208248 | C16: Thạch Khái | D16: Vinh | E16: 11DHTP12 | F16: 0
A17: 11 | B17: 2005208528 | C17: Dương Hoàng Tuấn | D17: Anh | E17: 11DHTP13 | F17: 3 | G17: Yakult | H17: 45602 | I17: Offline | J17: 8 | L17: Kewpie | M17: 45636 | N17: Offline | O17: 7 | Q17: Kewpie | R17: 24/20/2024 | S17: Offline | T17: 7
A18: 12 | B18: 2005208193 | C18: Phan Việt | D18: Hoàng | E18: 11DHTP14 | F18: 0
A19: 13 | B19: 2041214001 | C19: Lê | D19: Công | E19: 12DHQTTP02 | F19: 2 | G19: Aeon | H19: 45552 | I19: Offline | L19: Kewpie | M19: 45559 | N19: Offline | O19: 7.5
A20: 14 | B20: 2041214018 | C20: Nguyễn Duy | D20: Hiếu | E20: 12DHQTTP02 | F20: 1 | G20: Acecook | H20: 45784 | I20: Offline | J20: 7
A21: 15 | B21: 2041210256 | C21: Nguyễn Thị Thanh | D21: Kiều | E21: 12DHQTTP02 | F21: 0
A22: 16 | B22: 2041210213 | C22: Nguyễn Phương | D22: Lâm | E22: 12DHQTTP02 | F22: 0
A23: 17 | B23: 2041214058 | C23: Lê Thị Thảo | D23: Nguyên | E23: 12DHQTTP02 | F23: 3 | G23: Yakult | H23: 45602 | I23: Offline | J23: 4.5 | L23: Satori | M23: 45629 | N23: Offline | O23: 8.5 | P23: 0.5 | Q23: Acecook | R23: 45631 | S23: Offline | T23: 5.5
A24: 18 | B24: 2041214028 | C24: Nguyễn Trung | D24: Kiên | E24: 12DHQTTP03 | F24: 0
A25: 19 | B25: 2041214070 | C25: Đặng Minh | D25: Phương | E25: 12DHQTTP03 | F25: 2 | G25: Kewpie | H25: 45356 | I25: Offline | J25: 5.5 | L25: Acecook | M25: 45399 | N25: Offline | O25: 7
A26: 20 | B26: 2041210181 | C26: Ngô Quang | D26: Huy | E26: 12DHQTTP04 | F26: 2 | G26: Kewpie | H26: 45589 | I26: Offline | J26: 6 | L26: Acecook | M26: 45471 | N26: Offline | O26: 8
A27: 21 | B27: 2041214026 | C27: Nguyễn Thị | D27: Hương | E27: 12DHQTTP04 | F27: 1 | G27: Yakult | H27: 45637 | I27: Offline | J27: 6.5
A28: 22 | B28: 2041210264 | C28: Huỳnh Thị Kim | D28: Ngân | E28: 12DHQTTP04 | F28: 1 | G28: Acecook | H28: 45721 | I28: Offline | J28: 7.5
A29: 23 | B29: 2041214067 | C29: Vi Thị Quỳnh | D29: Như | E29: 12DHQTTP04 | F29: 2 | G29: Acecook | H29: 45455 | I29: Offline | J29: 8.5 | L29: Yakult | M29: 45803 | N29: Offline | O29: 8.5
A30: 24 | B30: 2041210176 | C30: Đinh Nguyễn Quang | D30: Tiến | E30: 12DHQTTP04 | F30: 3 | G30: Kewpie | H30: 45589 | I30: Offline | J30: 4 | L30: Acecook | M30: 45443 | N30: Offline | O30: 4.5 | Q30: Acecook | R30: 45471 | S30: Offline | T30: 6.5
A31: 25 | B31: 2041210175 | C31: Đỗ Thanh | D31: Thảo | E31: 12DHQTTP04 | F31: 2 | G31: Yakult | H31: 45629 | I31: Offline | J31: 9 | L31: Acecook | M31: 45436 | N31: Offline | O31: 6.5
A32: 26 | B32: 2041214109 | C32: Phạm Ngọc Thảo | D32: Vi | E32: 12DHQTTP04 | F32: 5 | G32: Kewpie | H32: 45391 | I32: Offline | J32: 5.5 | L32: Acecook | M32: 45422 | N32: Offline | O32: 7 | Q32: Acecook | R32: 45455 | S32: Offline | T32: 8 | V32: Satori | W32: 45797 | X32: Offline | Y32: 6 | AA32: Yakult | AB32: 45803 | AC32: Offline | AD32: 7
A33: 27 | B33: 2041214113 | C33: Nguyễn Ngọc Thảo | D33: Vy | E33: 12DHQTTP04 | F33: 1 | G33: Acecook | H33: 45422 | I33: Offline | J33: 7
A34: 28 | B34: 2005210982 | C34: Huỳnh Quốc | D34: Cường | E34: 12DHTP01 | F34: 4 | G34: Yakult | H34: 45602 | I34: Offline | J34: 7 | L34: Satori | M34: 45629 | N34: Offline | O34: 7 | Q34: Acecook | R34: 45721 | S34: Offline | T34: 8.5 | V34: Yakult | W34: 45803 | X34: Offline | Y34: 8
A35: 29 | B35: 2005210184 | C35: Lưu Nguyễn Quế | D35: Hương | E35: 12DHTP02 | F35: 2 | G35: Kewpie | H35: 45405 | I35: Offline | J35: 7 | L35: Acecook | M35: 45436 | N35: Offline | O35: 7.5
A36: 30 | B36: 2005210209 | C36: Đinh Minh | D36: Nhã | E36: 12DHTP02 | F36: 4 | G36: Yakult | H36: 45602 | I36: Offline | J36: 8.5 | L36: Acecook | M36: 45631 | N36: Offline | O36: 8.5 | Q36: Kewpie | R36: 45559 | S36: Offline | T36: 8 | V36: Acecook | W36: 45422 | X36: Offline | Y36: 7.5
A37: 31 | B37: 2005210573 | C37: Nguyễn Viết Nhật | D37: Huy | E37: 12DHTP03 | F37: 0
A38: 32 | B38: 2005211043 | C38: Phạm Minh | D38: Khang | E38: 12DHTP03 | F38: 1 | G38: Yakult | H38: 45602 | I38: Offline | J38: 6
A39: 33 | B39: 2005211255 | C39: Nguyễn Bảo | D39: Trân | E39: 12DHTP03 | F39: 2 | G39: Yakult | H39: 45645 | I39: Offline | J39: 6 | L39: Yakult | M39: 45817 | N39: Offline | O39: 8
A40: 34 | B40: 2005210553 | C40: Huỳnh Dương Trọng | D40: Phúc | E40: 12DHTP05 | F40: 2 | G40: Yakult | H40: 45817 | I40: Offline | J40: 10 | L40: Kewpie | M40: 45818 | N40: Offline | O40: 8.5
A41: 35 | B41: 2005211085 | C41: Hồ Hải | D41: Đăng | E41: 12DHTP06 | F41: 0
A42: 36 | B42: 2005211090 | C42: Võ Vân | D42: Anh | E42: 12DHTP07 | F42: 0
...

Sheet Nộp báo cáo
A1: Dữ liệu xuất lúc 8h00 ngày 12/6/2025
A2: MSSV | B2: =IFERROR(__xludf.DUMMYFUNCTION("""COMPUTED_VALUE"""),"Họ và tên") -> Họ và tên | C2: =IFERROR(__xludf.DUMMYFUNCTION("""COMPUTED_VALUE"""),"Lớp") -> Lớp | D2: =IFERROR(__xludf.DUMMYFUNCTION("""COMPUTED_VALUE"""),"Giảng viên hướng dẫn") -> Giảng viên hướng dẫn | E2: =IFERROR(__xludf.DUMMYFUNCTION("""COMPUTED_VALUE"""),"Tên nhà máy") -> Tên nhà máy | F2: =IFERROR(__xludf.DUMMYFUNCTION("""COMPUTED_VALUE"""),"Loại hình chuyến TQNM") -> Loại hình chuyến TQNM | G2: =IFERROR(__xludf.DUMMYFUNCTION("""COMPUTED_VALUE"""),"Hình thức tham quan nhà máy") -> Hình thức tham quan nhà máy
A3: 2041222734 | B3: Đỗ Ngọc Ái Mỹ | C3: 13DHQTTP03 | D3: Đỗ Mai Nguyên Phương | E3: CÔNG TY CỔ PHẦN ĐẦU TƯ VÀ THƯƠNG MẠI SATORI | F3: do Trường tổ chức | G3: trực tiếp (offline)
A4: 2041222734 | B4: Đỗ Ngọc Ái Mỹ | C4: 13DHQTTP03 | D4: Đỗ Mai Nguyên Phương | E4: Công ty TNHH Ajinomoto Việt Nam - Nhà máy Long Thành | F4: do Trường tổ chức | G4: trực tuyến (online)
A5: 2041220829 | B5: Đỗ Ngọc Thuỳ Dương | C5: 13DHQTTP03 | D5: Đỗ Mai Nguyên Phương | E5: Công ty TNHH Aeon Việt Nam | F5: do Trường tổ chức | G5: trực tiếp (offline)
A6: 2041220829 | B6: Đỗ Ngọc Thuỳ Dương | C6: 13DHQTTP03 | D6: Đỗ Mai Nguyên Phương | E6: Công ty TNHH Ajinomoto Việt Nam - Nhà máy Long Thành | F6: do Trường tổ chức | G6: trực tuyến (online)
A7: 2041220829 | B7: Đỗ Ngọc Thuỳ Dương | C7: 13DHQTTP03 | D7: Đỗ Mai Nguyên Phương | E7: Công ty TNHH Yakult Việt Nam | F7: do Trường tổ chức | G7: trực tiếp (offline)
A8: 2041224117 | B8: Đỗ Như Quỳnh | C8: 13DHQTTP02 | D8: Đỗ Mai Nguyên Phương | E8: Công ty TNHH Yakult Việt Nam | F8: do Trường tổ chức | G8: trực tiếp (offline)
A9: 2041224117 | B9: Đỗ Như Quỳnh | C9: 13DHQTTP02 | D9: Đỗ Mai Nguyên Phương | E9: CHI NHÁNH CTY CP TIẾN ĐỒNG - NHÀ MÁY BIA VINAKEN | F9: tự do | G9: trực tiếp (offline)
A10: 2041224117 | B10: Đỗ Như Quỳnh | C10: 13DHQTTP02 | D10: Đỗ Mai Nguyên Phương | E10: Công ty TNHH Ajinomoto Việt Nam - Nhà máy Long Thành | F10: do Trường tổ chức | G10: trực tuyến (online)
A11: 2041225111 | B11: Đỗ Thị Bích Thủy | C11: 13DHQTTP03 | D11: Đỗ Mai Nguyên Phương | E11: Công ty TNHH Yakult Việt Nam | F11: do Trường tổ chức | G11: trực tiếp (offline)
A12: 2041225111 | B12: Đỗ Thị Bích Thủy | C12: 13DHQTTP03 | D12: Đỗ Mai Nguyên Phương | E12: Công ty TNHH Ajinomoto Việt Nam - Nhà máy Long Thành | F12: do Trường tổ chức | G12: trực tuyến (online)
A13: 2041225111 | B13: Đỗ Thị Bích Thủy | C13: 13DHQTTP03 | D13: Đỗ Mai Nguyên Phương | E13: Công ty CP Acecook Việt Nam | F13: do Trường tổ chức | G13: trực tiếp (offline)
A14: 2041222515 | B14: Hồ Hải Lưu | C14: 13DHQTTP03 | D14: Đỗ Mai Nguyên Phương | E14: Công ty CP Acecook Việt Nam | F14: do Trường tổ chức | G14: trực tiếp (offline)
... A743: 2041224495 | B743: Nguyễn Thanh Tú | C743: 13DHQTTP03 | D743: Huỳnh Thị Lê Dung | E743: Công ty TNHH Kewpie Việt Nam | F743: do Trường tổ chức | G743: trực tiếp (offline)
A744: 2041224495 | B744: Nguyễn Thanh Tú | C744: 2041224495 | D744: Huỳnh Thị Lê Dung | E744: Công ty TNHH Ajinomoto Việt Nam - Nhà máy Long Thành | F744: do Trường tổ chức | G744: trực tuyến (online)
A745: 2041221449 | B745: Nguyễn Thị Hoa | C745: 13DHQTTP04 | D745: Huỳnh Thị Lê Dung | E745: Công ty CP Acecook Việt Nam | F745: do Trường tổ chức | G745: trực tiếp (offline)
A746: 2041221449 | B746: Nguyễn Thị Hoa | C746: 13DHQTTP04 | D746: Huỳnh Thị Lê Dung | E746: Công ty TNHH Yakult Việt Nam | F746: do Trường tổ chức | G746: trực tiếp (offline)
A747: 2041226245 | B747: Nguyễn Thị Ngọc Trăm | C747: 13DHQTTP04 | D747: Huỳnh Thị Lê Dung | E747: Công ty TNHH Aeon Việt Nam | F747: do Trường tổ chức | G747: trực tiếp (offline)
A748: 2041226245 | B748: Nguyễn Thị Ngọc Trăm | C748: 13DHQTTP04 | D748: Huỳnh Thị Lê Dung | E748: Công ty TNHH Yakult Việt Nam | F748: do Trường tổ chức | G748: trực tiếp (offline)
A749: 2041226245 | B749: Nguyễn Thị Ngọc Trăm | C749: 13DHQTTP04 | D749: Huỳnh Thị Lê Dung | E749: Công ty TNHH Ajinomoto Việt Nam - Nhà máy Long Thành | F749: do Trường tổ chức | G749: trực tuyến (online)
A750: 2041224116 | B750: Nguyễn Thị Như Quỳnh | C750: 13DHQTTP04 | D750: Huỳnh Thị Lê Dung | E750: Công ty TNHH Yakult Việt Nam | F750: do Trường tổ chức | G750: trực tiếp (offline)
A751: 2041224116 | B751: Nguyễn Thị Như Quỳnh | C751: 13DHQTTP04 | D751: Huỳnh Thị Lê Dung | E751: CÔNG TY CỔ PHẦN ĐẦU TƯ VÀ THƯƠNG MẠI SATORI | F751: do Trường tổ chức | G751: trực tiếp (offline)
A752: 2041224116 | B752: Nguyễn Thị Như Quỳnh | C752: 13DHQTTP04 | D752: Huỳnh Thị Lê Dung | E752: Công ty TNHH Ajinomoto Việt Nam - Nhà máy Long Thành | F752: do Trường tổ chức | G752: trực tuyến (online)
A753: 2041224139 | B753: Nguyễn Thị Thang Sang | C753: 13DHQTTP04 | D753: Huỳnh Thị Lê Dung | E753: Công ty TNHH Yakult Việt Nam | F753: do Trường tổ chức | G753: trực tiếp (offline)
A754: 2041224139 | B754: Nguyễn Thị Thanh Sang | C754: 13DHQTTP04 | D754: Huỳnh Thị Lê Dung | E754: Công ty TNHH Aeon Việt Nam | F754: do Trường tổ chức | G754: trực tiếp (offline)
A755: 2041224139 | B755: Nguyễn Thị Thanh Sang | C755: 13DHQTTP04 | D755: Huỳnh Thị Lê Dung | E755: Công ty TNHH Yakult Việt Nam | F755: do Trường tổ chức | G755: trực tiếp (offline)
A756: 2041224139 | B756: Nguyễn Thị Thanh Sang | C756: 13DHQTTP04 | D756: Huỳnh Thị Lê Dung | E756: Công ty TNHH Ajinomoto Việt Nam - Nhà máy Biên Hòa | F756: do Trường tổ chức | G756: trực tuyến (online)
... A1993: 2005230180 | B1993: Vũ Quốc Hoàng | C1993: 14DHTP04 | D1993: Vũ Thị Hường | E1993: CHI NHÁNH CTY CP TIẾN ĐỒNG - NHÀ MÁY BIA VINAKEN | F1993: do Trường tổ chức | G1993: trực tiếp (offline)

Sheet Danh sach kem GV
A1: STT | B1: Mã SV | C1: Họ Và Tên | E1: Ng/Sinh | F1: Tên lớp | G1: GVHD | H1: Ghi chú
A2: 1 | B2: 2022180145 | C2: Vũ Nguyễn Phương | D2: Nhi | E2: 31/10/2000 | F2: 09DHDB2 | G2: Huỳnh Thị Lê Dung
