Workbook

Sheet Dang ky_off
A1: DANH SÁCH SINH VIÊN THAM QUAN NHÀ MÁY
A3: STT | B3: MSSV | C3: Họ và tên | E3: Lớp | F3: Chữ kí | G3: Mã nhà máy | H3: Ngày TQNM | I3: Mã chuyến | J3: Tên NM | K3: Khoá chính (MASV+MANM) | L3: Điểm chuẩn bị | M3: Điểm thưởng | N3: Tình trạng nộp BC | O3: Hình thức đi | P3: GV dẫn đoàn | Q3: Kết quả lọc
A4: 1 | B4: 2005211255 | C4: =VLOOKUP(B4,'Phan mem'!$B$7:$D$1066,2,0) -> Nguyễn Bảo | D4: =VLOOKUP(B4,'Phan mem'!$B$7:$D$1066,3,0) -> Trân | E4: =VLOOKUP(B4,'Phan mem'!$B$7:$G$1066,6,0) -> 12DHTP03 | G4: ACE | H4: 45904 | I4: =G4&DAY(H4)&MONTH(H4)&YEAR(H4) -> ACE492025 | J4: =VLOOKUP(G4,'Nha may'!$B$2:$C$18,2,0) -> Công ty Cổ phần Acecook Việt Nam | K4: =B4&"-"&G4 -> 2005211255-ACE | L4: 8.5 | M4: 0 | O4: trực tiếp (offline) | P4: Nguyễn Văn Anh
A5: 2 | B5: 2041222032 | C5: =VLOOKUP(B5,'Phan mem'!$B$7:$D$1066,2,0) -> Ngô Hữu | D5: =VLOOKUP(B5,'Phan mem'!$B$7:$D$1066,3,0) -> Kháng | E5: =VLOOKUP(B5,'Phan mem'!$B$7:$G$1066,6,0) -> 13DHQTTP01 | G5: ACE | H5: 45904 | I5: =G5&DAY(H5)&MONTH(H5)&YEAR(H5) -> ACE492025 | J5: =VLOOKUP(G5,'Nha may'!$B$2:$C$18,2,0) -> Công ty Cổ phần Acecook Việt Nam | K5: =B5&"-"&G5 -> 2041222032-ACE | L5: 8.5 | M5: 0 | O5: trực tiếp (offline) | P5: Nguyễn Văn Anh
A6: 3 | B6: 2041224000 | C6: =VLOOKUP(B6,'Phan mem'!$B$7:$D$1066,2,0) -> Phạm Duy | D6: =VLOOKUP(B6,'Phan mem'!$B$7:$D$1066,3,0) -> Quý | E6: =VLOOKUP(B6,'Phan mem'!$B$7:$G$1066,6,0) -> 13DHQTTP01 | G6: ACE | H6: 45904 | I6: =G6&DAY(H6)&MONTH(H6)&YEAR(H6) -> ACE492025 | J6: =VLOOKUP(G6,'Nha may'!$B$2:$C$18,2,0) -> Công ty Cổ phần Acecook Việt Nam | K6: =B6&"-"&G6 -> 2041224000-ACE | L6: 8.5 | M6: 0 | O6: trực tiếp (offline) | P6: Nguyễn Văn Anh
A7: 4 | B7: 2041224874 | C7: =VLOOKUP(B7,'Phan mem'!$B$7:$D$1066,2,0) -> Phạm | D7: =VLOOKUP(B7,'Phan mem'!$B$7:$D$1066,3,0) -> Thân | E7: =VLOOKUP(B7,'Phan mem'!$B$7:$G$1066,6,0) -> 13DHQTTP01 | G7: ACE | H7: 45904 | I7: =G7&DAY(H7)&MONTH(H7)&YEAR(H7) -> ACE492025 | J7: =VLOOKUP(G7,'Nha may'!$B$2:$C$18,2,0) -> Công ty Cổ phần Acecook Việt Nam | K7: =B7&"-"&G7 -> 2041224874-ACE | L7: 9 | M7: 0 | O7: trực tiếp (offline) | P7: Nguyễn Văn Anh
A8: 5 | B8: 2041222925 | C8: =VLOOKUP(B8,'Phan mem'!$B$7:$D$1066,2,0) -> Đỗ Thanh | D8: =VLOOKUP(B8,'Phan mem'!$B$7:$D$1066,3,0) -> Ngân | E8: =VLOOKUP(B8,'Phan mem'!$B$7:$G$1066,6,0) -> 13DHQTTP02 | G8: ACE | H8: 45904 | I8: =G8&DAY(H8)&MONTH(H8)&YEAR(H8) -> ACE492025 | J8: =VLOOKUP(G8,'Nha may'!$B$2:$C$18,2,0) -> Công ty Cổ phần Acecook Việt Nam | K8: =B8&"-"&G8 -> 2041222925-ACE | L8: 8 | M8: 0 | O8: trực tiếp (offline) | P8: Nguyễn Văn Anh
A9: 6 | B9: 2041223058 | C9: =VLOOKUP(B9,'Phan mem'!$B$7:$D$1066,2,0) -> Huỳnh Thị Bích | D9: =VLOOKUP(B9,'Phan mem'!$B$7:$D$1066,3,0) -> Ngọc | E9: =VLOOKUP(B9,'Phan mem'!$B$7:$G$1066,6,0) -> 13DHQTTP02 | G9: ACE | H9: 45904 | I9: =G9&DAY(H9)&MONTH(H9)&YEAR(H9) -> ACE492025 | J9: =VLOOKUP(G9,'Nha may'!$B$2:$C$18,2,0) -> Công ty Cổ phần Acecook Việt Nam | K9: =B9&"-"&G9 -> 2041223058-ACE | L9: 9.5 | M9: 0 | O9: trực tiếp (offline) | P9: Nguyễn Văn Anh
A10: 7 | B10: 2041220592 | C10: =VLOOKUP(B10,'Phan mem'!$B$7:$D$1066,2,0) -> Nguyễn Lê Hồng | D10: =VLOOKUP(B10,'Phan mem'!$B$7:$D$1066,3,0) -> Diễm | E10: =VLOOKUP(B10,'Phan mem'!$B$7:$G$1066,6,0) -> 13DHQTTP03 | G10: ACE | H10: 45904 | I10: =G10&DAY(H10)&MONTH(H10)&YEAR(H10) -> ACE492025 | J10: =VLOOKUP(G10,'Nha may'!$B$2:$C$18,2,0) -> Công ty Cổ phần Acecook Việt Nam | K10: =B10&"-"&G10 -> 2041220592-ACE | L10: 6 | M10: 0 | O10: trực tiếp (offline) | P10: Nguyễn Văn Anh
A11: 8 | B11: 2041224669 | C11: =VLOOKUP(B11,'Phan mem'!$B$7:$D$1066,2,0) -> Vũ Lan | D11: =VLOOKUP(B11,'Phan mem'!$B$7:$D$1066,3,0) -> Thanh | E11: =VLOOKUP(B11,'Phan mem'!$B$7:$G$1066,6,0) -> 13DHQTTP03 | G11: ACE | H11: 45904 | I11: =G11&DAY(H11)&MONTH(H11)&YEAR(H11) -> ACE492025 | J11: =VLOOKUP(G11,'Nha may'!$B$2:$C$18,2,0) -> Công ty Cổ phần Acecook Việt Nam | K11: =B11&"-"&G11 -> 2041224669-ACE | L11: 6 | M11: 0 | O11: trực tiếp (offline) | P11: Nguyễn Văn Anh
A12: 9 | B12: 2005220812 | C12: =VLOOKUP(B12,'Phan mem'!$B$7:$D$1066,2,0) -> Nguyễn Thị Thùy | D12: =VLOOKUP(B12,'Phan mem'!$B$7:$D$1066,3,0) -> Dương | E12: =VLOOKUP(B12,'Phan mem'!$B$7:$G$1066,6,0) -> 13DHTP04 | G12: ACE | H12: 45904 | I12: =G12&DAY(H12)&MONTH(H12)&YEAR(H12) -> ACE492025 | J12: =VLOOKUP(G12,'Nha may'!$B$2:$C$18,2,0) -> Công ty Cổ phần Acecook Việt Nam | K12: =B12&"-"&G12 -> 2005220812-ACE | L12: 9 | M12: 0 | O12: trực tiếp (offline) | P12: Nguyễn Văn Anh
A13: 10 | B13: 2005222506 | C13: =VLOOKUP(B13,'Phan mem'!$B$7:$D$1066,2,0) -> Phạm Tấn | D13: =VLOOKUP(B13,'Phan mem'!$B$7:$D$1066,3,0) -> Lực | E13: =VLOOKUP(B13,'Phan mem'!$B$7:$G$1066,6,0) -> 13DHTP05 | G13: ACE | H13: 45904 | I13: =G13&DAY(H13)&MONTH(H13)&YEAR(H13) -> ACE492025 | J13: =VLOOKUP(G13,'Nha may'!$B$2:$C$18,2,0) -> Công ty Cổ phần Acecook Việt Nam | K13: =B13&"-"&G13 -> 2005222506-ACE | L13: 9 | M13: 0 | O13: trực tiếp (offline) | P13: Nguyễn Văn Anh
A14: 11 | B14: 2005220037 | C14: =VLOOKUP(B14,'Phan mem'!$B$7:$D$1066,2,0) -> Phạm Thúy | D14: =VLOOKUP(B14,'Phan mem'!$B$7:$D$1066,3,0) -> An | E14: =VLOOKUP(B14,'Phan mem'!$B$7:$G$1066,6,0) -> 13DHTP06 | G14: ACE | H14: 45904 | I14: =G14&DAY(H14)&MONTH(H14)&YEAR(H14) -> ACE492025 | J14: =VLOOKUP(G14,'Nha may'!$B$2:$C$18,2,0) -> Công ty Cổ phần Acecook Việt Nam | K14: =B14&"-"&G14 -> 2005220037-ACE | L14: 8.5 | M14: 0 | O14: trực tiếp (offline) | P14: Nguyễn Văn Anh
A15: 12 | B15: 2005220581 | C15: =VLOOKUP(B15,'Phan mem'!$B$7:$D$1066,2,0) -> Mai Thị Kim | D15: =VLOOKUP(B15,'Phan mem'!$B$7:$D$1066,3,0) -> Diểm | E15: =VLOOKUP(B15,'Phan mem'!$B$7:$G$1066,6,0) -> 13DHTP06 | G15: ACE | H15: 45904 | I15: =G15&DAY(H15)&MONTH(H15)&YEAR(H15) -> ACE492025 | J15: =VLOOKUP(G15,'Nha may'!$B$2:$C$18,2,0) -> Công ty Cổ phần Acecook Việt Nam | K15: =B15&"-"&G15 -> 2005220581-ACE | L15: 9.5 | M15: 0 | O15: trực tiếp (offline) | P15: Nguyễn Văn Anh
... A43: 40 | B43: 2022218304 | C43: =VLOOKUP(B43,'Phan mem'!$B$7:$D$1066,2,0) -> Nguyễn Thuận | D43: =VLOOKUP(B43,'Phan mem'!$B$7:$D$1066,3,0) -> Phát | E43: =VLOOKUP(B43,'Phan mem'!$B$7:$G$1066,6,0) -> 12DHDB04 | G43: ACE | H43: 45909 | I43: =G43&DAY(H43)&MONTH(H43)&YEAR(H43) -> ACE992025 | J43: =VLOOKUP(G43,'Nha may'!$B$2:$C$18,2,0) -> Công ty Cổ phần Acecook Việt Nam | K43: =B43&"-"&G43 -> 2022218304-ACE | L43: 8 | M43: 0 | O43: trực tiếp (offline) | P43: Đỗ Vĩnh Long
A44: 41 | B44: 2005217995 | C44: =VLOOKUP(B44,'Phan mem'!$B$7:$D$1066,2,0) -> Huỳnh Ngọc Yến | D44: =VLOOKUP(B44,'Phan mem'!$B$7:$D$1066,3,0) -> Nhi | E44: =VLOOKUP(B44,'Phan mem'!$B$7:$G$1066,6,0) -> 12DHTP07 | G44: ACE | H44: 45909 | J44: =VLOOKUP(G44,'Nha may'!$B$2:$C$18,2,0) -> Công ty Cổ phần Acecook Việt Nam | L44: 8.5 | M44: 0 | O44: trực tiếp (offline) | P44: Đỗ Vĩnh Long
A45: 42 | B45: 2041223473 | C45: =VLOOKUP(B45,'Phan mem'!$B$7:$D$1066,2,0) -> Bùi Phạm Quỳnh | D45: =VLOOKUP(B45,'Phan mem'!$B$7:$D$1066,3,0) -> Như | E45: =VLOOKUP(B45,'Phan mem'!$B$7:$G$1066,6,0) -> 13DHQTTP01 | G45: ACE | H45: 45909 | J45: =VLOOKUP(G45,'Nha may'!$B$2:$C$18,2,0) -> Công ty Cổ phần Acecook Việt Nam | L45: 9 | M45: 0 | O45: trực tiếp (offline) | P45: Đỗ Vĩnh Long
A46: 43 | B46: 2041223898 | C46: =VLOOKUP(B46,'Phan mem'!$B$7:$D$1066,2,0) -> Đào Thị Mỹ | D46: =VLOOKUP(B46,'Phan mem'!$B$7:$D$1066,3,0) -> Phượng | E46: =VLOOKUP(B46,'Phan mem'!$B$7:$G$1066,6,0) -> 13DHQTTP01 | G46: ACE | H46: 45909 | J46: =VLOOKUP(G46,'Nha may'!$B$2:$C$18,2,0) -> Công ty Cổ phần Acecook Việt Nam | L46: 7.5 | M46: 0 | O46: trực tiếp (offline) | P46: Đỗ Vĩnh Long
A47: 44 | B47: 2041220767 | C47: =VLOOKUP(B47,'Phan mem'!$B$7:$D$1066,2,0) -> Lâm Thùy | D47: =VLOOKUP(B47,'Phan mem'!$B$7:$D$1066,3,0) -> Duyên | E47: =VLOOKUP(B47,'Phan mem'!$B$7:$G$1066,6,0) -> 13DHQTTP02 | G47: ACE | H47: 45909 | J47: =VLOOKUP(G47,'Nha may'!$B$2:$C$18,2,0) -> Công ty Cổ phần Acecook Việt Nam | L47: 7.5 | M47: 0 | O47: trực tiếp (offline) | P47: Đỗ Vĩnh Long
A48: 45 | B48: 2041222189 | C48: =VLOOKUP(B48,'Phan mem'!$B$7:$D$1066,2,0) -> Trần Anh Mai | D48: =VLOOKUP(B48,'Phan mem'!$B$7:$D$1066,3,0) -> Lan | E48: =VLOOKUP(B48,'Phan mem'!$B$7:$G$1066,6,0) -> 13DHQTTP02 | G48: ACE | H48: 45909 | J48: =VLOOKUP(G48,'Nha may'!$B$2:$C$18,2,0) -> Công ty Cổ phần Acecook Việt Nam | L48: 9 | M48: 0 | O48: trực tiếp (offline) | P48: Đỗ Vĩnh Long
A49: 46 | B49: 2041224029 | C49: =VLOOKUP(B49,'Phan mem'!$B$7:$D$1066,2,0) -> Dương Kim | D49: =VLOOKUP(B49,'Phan mem'!$B$7:$D$1066,3,0) -> Quyên | E49: =VLOOKUP(B49,'Phan mem'!$B$7:$G$1066,6,0) -> 13DHQTTP02 | G49: ACE | H49: 45909 | J49: =VLOOKUP(G49,'Nha may'!$B$2:$C$18,2,0) -> Công ty Cổ phần Acecook Việt Nam | L49: 9.5 | M49: 0 | O49: trực tiếp (offline) | P49: Đỗ Vĩnh Long
A50: 47 | B50: 2041224348 | C50: =VLOOKUP(B50,'Phan mem'!$B$7:$D$1066,2,0) -> Ngô Thụy Thủy | D50: =VLOOKUP(B50,'Phan mem'!$B$7:$D$1066,3,0) -> Tiên | E50: =VLOOKUP(B50,'Phan mem'!$B$7:$G$1066,6,0) -> 13DHQTTP02 | G50: ACE | H50: 45909 | J50: =VLOOKUP(G50,'Nha may'!$B$2:$C$18,2,0) -> Công ty Cổ phần Acecook Việt Nam | L50: 9.5 | M50: 0 | O50: trực tiếp (offline) | P50: Đỗ Vĩnh Long
A51: 48 | B51: 2005220778 | C51: =VLOOKUP(B51,'Phan mem'!$B$7:$D$1066,2,0) -> Từ Ngọc Mỹ | D51: =VLOOKUP(B51,'Phan mem'!$B$7:$D$1066,3,0) -> Duyên | E51: =VLOOKUP(B51,'Phan mem'!$B$7:$G$1066,6,0) -> 13DHTP02 | G51: ACE | H51: 45909 | J51: =VLOOKUP(G51,'Nha may'!$B$2:$C$18,2,0) -> Công ty Cổ phần Acecook Việt Nam | L51: 7.5 | M51: 0 | O51: trực tiếp (offline) | P51: Đỗ Vĩnh Long
A52: 49 | B52: 2005224276 | C52: =VLOOKUP(B52,'Phan mem'!$B$7:$D$1066,2,0) -> Lê Nguyễn Hoàng | D52: =VLOOKUP(B52,'Phan mem'!$B$7:$D$1066,3,0) -> Tâm | E52: =VLOOKUP(B52,'Phan mem'!$B$7:$G$1066,6,0) -> 13DHTP02 | G52: ACE | H52: 45909 | J52: =VLOOKUP(G52,'Nha may'!$B$2:$C$18,2,0) -> Công ty Cổ phần Acecook Việt Nam | L52: 9.5 | M52: 0 | O52: trực tiếp (offline) | P52: Đỗ Vĩnh Long
A53: 50 | B53: 2005222625 | C53: =VLOOKUP(B53,'Phan mem'!$B$7:$D$1066,2,0) -> Thái Bình | D53: =VLOOKUP(B53,'Phan mem'!$B$7:$D$1066,3,0) -> Minh | E53: =VLOOKUP(B53,'Phan mem'!$B$7:$G$1066,6,0) -> 13DHTP03 | G53: ACE | H53: 45909 | J53: =VLOOKUP(G53,'Nha may'!$B$2:$C$18,2,0) -> Công ty Cổ phần Acecook Việt Nam | L53: 5.5 | M53: 0 | O53: trực tiếp (offline) | P53: Đỗ Vĩnh Long
A54: 51 | B54: 2005221545 | C54: =VLOOKUP(B54,'Phan mem'!$B$7:$D$1066,2,0) -> Nguyễn Cửu | D54: =VLOOKUP(B54,'Phan mem'!$B$7:$D$1066,3,0) -> Huân | E54: =VLOOKUP(B54,'Phan mem'!$B$7:$G$1066,6,0) -> 13DHTP04 | G54: ACE | H54: 45909 | J54: =VLOOKUP(G54,'Nha may'!$B$2:$C$18,2,0) -> Công ty Cổ phần Acecook Việt Nam | L54: 9.5 | M54: 0 | O54: trực tiếp (offline) | P54: Đỗ Vĩnh Long
A55: 52 | B55: 2005221990 | C55: =VLOOKUP(B55,'Phan mem'!$B$7:$D$1066,2,0) -> Ngô Yên | D55: =VLOOKUP(B55,'Phan mem'!$B$7:$D$1066,3,0) -> Khang | E55: =VLOOKUP(B55,'Phan mem'!$B$7:$G$1066,6,0) -> 13DHTP04 | G55: ACE | H55: 45909 | J55: =VLOOKUP(G55,'Nha may'!$B$2:$C$18,2,0) -> Công ty Cổ phần Acecook Việt Nam | L55: 9.5 | M55: 0 | O55: trực tiếp (offline) | P55: Đỗ Vĩnh Long
... A77: 74 | B77: 2005230667 | C77: =VLOOKUP(B77,'Phan mem'!$B$7:$D$1066,2,0) -> Trần Thị Yến | D77: =VLOOKUP(B77,'Phan mem'!$B$7:$D$1066,3,0) -> Vy | E77: =VLOOKUP(B77,'Phan mem'!$B$7:$G$1066,6,0) -> 14DHTP10 | G77: ACE | H77: 45909 | J77: =VLOOKUP(G77,'Nha may'!$B$2:$C$18,2,0) -> Công ty Cổ phần Acecook Việt Nam | L77: 8.5 | M77: 0 | O77: trực tiếp (offline) | P77: Đỗ Vĩnh Long
A78: 75 | B78: 2041220738 | C78: =VLOOKUP(B78,'Phan mem'!$B$7:$D$1066,2,0) -> Tạ Phạm Anh | D78: =VLOOKUP(B78,'Phan mem'!$B$7:$D$1066,3,0) -> Duy | E78: =VLOOKUP(B78,'Phan mem'!$B$7:$G$1066,6,0) -> 13DHQTTP01 | G78: ACE | H78: 45932 | J78: =VLOOKUP(G78,'Nha may'!$B$2:$C$18,2,0) -> Công ty Cổ phần Acecook Việt Nam | L78: 9 | O78: trực tiếp (offline) | P78: Lâm Thế Hải
A79: 76 | B79: 2005223444 | C79: =VLOOKUP(B79,'Phan mem'!$B$7:$D$1066,2,0) -> Thượng Thị Hồng | D79: =VLOOKUP(B79,'Phan mem'!$B$7:$D$1066,3,0) -> Nhung | E79: =VLOOKUP(B79,'Phan mem'!$B$7:$G$1066,6,0) -> 13DHTP01 | G79: ACE | H79: 45932 | J79: =VLOOKUP(G79,'Nha may'!$B$2:$C$18,2,0) -> Công ty Cổ phần Acecook Việt Nam | L79: 6 | O79: trực tiếp (offline) | P79: Lâm Thế Hải
A80: 77 | B80: 2005222726 | C80: =VLOOKUP(B80,'Phan mem'!$B$7:$D$1066,2,0) -> Lê Hoàng Như | D80: =VLOOKUP(B80,'Phan mem'!$B$7:$D$1066,3,0) -> Mỹ | E80: =VLOOKUP(B80,'Phan mem'!$B$7:$G$1066,6,0) -> 13DHTP06 | G80: ACE | H80: 45932 | J80: =VLOOKUP(G80,'Nha may'!$B$2:$C$18,2,0) -> Công ty Cổ phần Acecook Việt Nam | L80: 8.5 | O80: trực tiếp (offline) | P80: Lâm Thế Hải
A81: 78 | B81: 2041230232 | C81: =VLOOKUP(B81,'Phan mem'!$B$7:$D$1066,2,0) -> Thái Hà | D81: =VLOOKUP(B81,'Phan mem'!$B$7:$D$1066,3,0) -> Tú | E81: =VLOOKUP(B81,'Phan mem'!$B$7:$G$1066,6,0) -> 14DHQTTP01 | G81: ACE | H81: 45932 | J81: =VLOOKUP(G81,'Nha may'!$B$2:$C$18,2,0) -> Công ty Cổ phần Acecook Việt Nam | L81: 9.5 | O81: trực tiếp (offline) | P81: Lâm Thế Hải
A82: 79 | B82: 2041230241 | C82: =VLOOKUP(B82,'Phan mem'!$B$7:$D$1066,2,0) -> Thái Hà | D82: =VLOOKUP(B82,'Phan mem'!$B$7:$D$1066,3,0) -> Thanh | E82: =VLOOKUP(B82,'Phan mem'!$B$7:$G$1066,6,0) -> 14DHQTTP01 | G82: ACE | H82: 45932 | J82: =VLOOKUP(G82,'Nha may'!$B$2:$C$18,2,0) -> Công ty Cổ phần Acecook Việt Nam | L82: 8 | O82: trực tiếp (offline) | P82: Lâm Thế Hải
A83: 80 | B83: 2005230084 | C83: =VLOOKUP(B83,'Phan mem'!$B$7:$D$1066,2,0) -> Lê Bảo | D83: =VLOOKUP(B83,'Phan mem'!$B$7:$D$1066,3,0) -> Duy | E83: =VLOOKUP(B83,'Phan mem'!$B$7:$G$1066,6,0) -> 14DHTP_TD | G83: ACE | H83: 45932 | J83: =VLOOKUP(G83,'Nha may'!$B$2:$C$18,2,0) -> Công ty Cổ phần Acecook Việt Nam | L83: 8 | O83: trực tiếp (offline) | P83: Lâm Thế Hải
A84: 81 | B84: 2005230111 | C84: =VLOOKUP(B84,'Phan mem'!$B$7:$D$1066,2,0) -> Lê Tuấn | D84: =VLOOKUP(B84,'Phan mem'!$B$7:$D$1066,3,0) -> Đạt | E84: =VLOOKUP(B84,'Phan mem'!$B$7:$G$1066,6,0) -> 14DHTP_TD | G84: ACE | H84: 45932 | J84: =VLOOKUP(G84,'Nha may'!$B$2:$C$18,2,0) -> Công ty Cổ phần Acecook Việt Nam | L84: 6.5 | O84: trực tiếp (offline) | P84: Lâm Thế Hải
A85: 82 | B85: 2005230452 | C85: =VLOOKUP(B85,'Phan mem'!$B$7:$D$1066,2,0) -> Nguyễn Phạm Hồng | D85: =VLOOKUP(B85,'Phan mem'!$B$7:$D$1066,3,0) -> Phượng | E85: =VLOOKUP(B85,'Phan mem'!$B$7:$G$1066,6,0) -> 14DHTP_TD | G85: ACE | H85: 45932 | J85: =VLOOKUP(G85,'Nha may'!$B$2:$C$18,2,0) -> Công ty Cổ phần Acecook Việt Nam | L85: 7 | O85: trực tiếp (offline) | P85: Lâm Thế Hải
A86: 83 | B86: 2005230091 | C86: =VLOOKUP(B86,'Phan mem'!$B$7:$D$1066,2,0) -> Sầm Nhật | D86: =VLOOKUP(B86,'Phan mem'!$B$7:$D$1066,3,0) -> Duy | E86: =VLOOKUP(B86,'Phan mem'!$B$7:$G$1066,6,0) -> 14DHTP03 | G86: ACE | H86: 45932 | J86: =VLOOKUP(G86,'Nha may'!$B$2:$C$18,2,0) -> Công ty Cổ phần Acecook Việt Nam | L86: 9 | M86: 0.5 | O86: trực tiếp (offline) | P86: Lâm Thế Hải
A87: 84 | B87: 2005230213 | C87: =VLOOKUP(B87,'Phan mem'!$B$7:$D$1066,2,0) -> Nguyễn Trung | D87: =VLOOKUP(B87,'Phan mem'!$B$7:$D$1066,3,0) -> Kiên | E87: =VLOOKUP(B87,'Phan mem'!$B$7:$G$1066,6,0) -> 14DHTP03 | G87: ACE | H87: 45932 | J87: =VLOOKUP(G87,'Nha may'!$B$2:$C$18,2,0) -> Công ty Cổ phần Acecook Việt Nam | L87: 8.5 | O87: trực tiếp (offline) | P87: Lâm Thế Hải
A88: 85 | B88: 2005230224 | C88: =VLOOKUP(B88,'Phan mem'!$B$7:$D$1066,2,0) -> Trần Phú An | D88: =VLOOKUP(B88,'Phan mem'!$B$7:$D$1066,3,0) -> Khang | E88: =VLOOKUP(B88,'Phan mem'!$B$7:$G$1066,6,0) -> 14DHTP03 | G88: ACE | H88: 45932 | J88: =VLOOKUP(G88,'Nha may'!$B$2:$C$18,2,0) -> Công ty Cổ phần Acecook Việt Nam | L88: 8 | M88: 0.5 | O88: trực tiếp (offline) | P88: Lâm Thế Hải
A89: 86 | B89: 2005230222 | C89: =VLOOKUP(B89,'Phan mem'!$B$7:$D$1066,2,0) -> Nguyễn Trọng | D89: =VLOOKUP(B89,'Phan mem'!$B$7:$D$1066,3,0) -> Khang | E89: =VLOOKUP(B89,'Phan mem'!$B$7:$G$1066,6,0) -> 14DHTP03 | G89: ACE | H89: 45932 | J89: =VLOOKUP(G89,'Nha may'!$B$2:$C$18,2,0) -> Công ty Cổ phần Acecook Việt Nam | L89: 9 | O89: trực tiếp (offline) | P89: Lâm Thế Hải
...

Sheet Dang ky_onl
A1: Nếu được duyệt cho mỗi mã SV 2 nhà máy khác nhau, lưu ý: nhập mã SV trùng nhà máy là không cho (MaSV, MaNM)
A3: DANH SÁCH SINH VIÊN THAM QUAN NHÀ MÁY
A5: STT | B5: MSSV | C5: Họ và tên | E5: Lớp | F5: Chữ kí | G5: Mã nhà máy | H5: Ngày TQNM | I5: Mã chuyến | J5: Tên NM | K5: Khoá chính (MASV+MANM) | L5: Điểm chuẩn bị | M5: Điểm thưởng | N5: Tình trạng nộp BC | O5: Hình thức đi | P5: GVHD | Q5: Kết quả lọc
A6: 1 | C6: =VLOOKUP(B6,'Phan mem'!$B$7:$D$1019,2,0) -> #N/A | D6: =VLOOKUP(B6,'Phan mem'!$B$7:$D$1019,3,0) -> #N/A | E6: =VLOOKUP(B6,'Phan mem'!$B$7:$G$1019,6,0) -> #N/A | I6: =G6&DAY(H6)&MONTH(H6)&YEAR(H6) -> 011900 | J6: =VLOOKUP(G6,'Nha may'!$B$2:$C$18,2,0) -> #N/A | K6: =B6&"-"&G6 -> -
A7: 2 | C7: =VLOOKUP(B7,'Phan mem'!$B$7:$D$1019,2,0) -> #N/A | D7: =VLOOKUP(B7,'Phan mem'!$B$7:$D$1019,3,0) -> #N/A | E7: =VLOOKUP(B7,'Phan mem'!$B$7:$G$1019,6,0) -> #N/A | I7: =G7&DAY(H7)&MONTH(H7)&YEAR(H7) -> 011900 | J7: =VLOOKUP(G7,'Nha may'!$B$2:$C$18,2,0) -> #N/A | K7: =B7&"-"&G7 -> -
A8: 3 | C8: =VLOOKUP(B8,'Phan mem'!$B$7:$D$1019,2,0) -> #N/A | D8: =VLOOKUP(B8,'Phan mem'!$B$7:$D$1019,3,0) -> #N/A | E8: =VLOOKUP(B8,'Phan mem'!$B$7:$G$1019,6,0) -> #N/A | I8: =G8&DAY(H8)&MONTH(H8)&YEAR(H8) -> 011900 | J8: =VLOOKUP(G8,'Nha may'!$B$2:$C$18,2,0) -> #N/A | K8: =B8&"-"&G8 -> -
A9: 4 | C9: =VLOOKUP(B9,'Phan mem'!$B$7:$D$1019,2,0) -> #N/A | D9: =VLOOKUP(B9,'Phan mem'!$B$7:$D$1019,3,0) -> #N/A | E9: =VLOOKUP(B9,'Phan mem'!$B$7:$G$1019,6,0) -> #N/A | I9: =G9&DAY(H9)&MONTH(H9)&YEAR(H9) -> 011900 | J9: =VLOOKUP(G9,'Nha may'!$B$2:$C$18,2,0) -> #N/A | K9: =B9&"-"&G9 -> -
A10: 5 | C10: =VLOOKUP(B10,'Phan mem'!$B$7:$D$1019,2,0) -> #N/A | D10: =VLOOKUP(B10,'Phan mem'!$B$7:$D$1019,3,0) -> #N/A | E10: =VLOOKUP(B10,'Phan mem'!$B$7:$G$1019,6,0) -> #N/A | I10: =G10&DAY(H10)&MONTH(H10)&YEAR(H10) -> 011900 | J10: =VLOOKUP(G10,'Nha may'!$B$2:$C$18,2,0) -> #N/A | K10: =B10&"-"&G10 -> -
A11: 6 | C11: =VLOOKUP(B11,'Phan mem'!$B$7:$D$1019,2,0) -> #N/A | D11: =VLOOKUP(B11,'Phan mem'!$B$7:$D$1019,3,0) -> #N/A | E11: =VLOOKUP(B11,'Phan mem'!$B$7:$G$1019,6,0) -> #N/A | I11: =G11&DAY(H11)&MONTH(H11)&YEAR(H11) -> 011900 | J11: =VLOOKUP(G11,'Nha may'!$B$2:$C$18,2,0) -> #N/A | K11: =B11&"-"&G11 -> -
A12: 7 | C12: =VLOOKUP(B12,'Phan mem'!$B$7:$D$1019,2,0) -> #N/A | D12: =VLOOKUP(B12,'Phan mem'!$B$7:$D$1019,3,0) -> #N/A | E12: =VLOOKUP(B12,'Phan mem'!$B$7:$G$1019,6,0) -> #N/A | I12: =G12&DAY(H12)&MONTH(H12)&YEAR(H12) -> 011900 | J12: =VLOOKUP(G12,'Nha may'!$B$2:$C$18,2,0) -> #N/A | K12: =B12&"-"&G12 -> -
A13: 12 | C13: =VLOOKUP(B13,'Phan mem'!$B$7:$D$1019,2,0) -> #N/A | D13: =VLOOKUP(B13,'Phan mem'!$B$7:$D$1019,3,0) -> #N/A | E13: =VLOOKUP(B13,'Phan mem'!$B$7:$G$1019,6,0) -> #N/A | I13: =G13&DAY(H13)&MONTH(H13)&YEAR(H13) -> 011900 | J13: =VLOOKUP(G13,'Nha may'!$B$2:$C$18,2,0) -> #N/A | K13: =B13&"-"&G13 -> -
A14: 13 | C14: =VLOOKUP(B14,'Phan mem'!$B$7:$D$1019,2,0) -> #N/A | D14: =VLOOKUP(B14,'Phan mem'!$B$7:$D$1019,3,0) -> #N/A | E14: =VLOOKUP(B14,'Phan mem'!$B$7:$G$1019,6,0) -> #N/A | I14: =G14&DAY(H14)&MONTH(H14)&YEAR(H14) -> 011900 | J14: =VLOOKUP(G14,'Nha may'!$B$2:$C$18,2,0) -> #N/A | K14: =B14&"-"&G14 -> -
A15: 14 | C15: =VLOOKUP(B15,'Phan mem'!$B$7:$D$1019,2,0) -> #N/A | D15: =VLOOKUP(B15,'Phan mem'!$B$7:$D$1019,3,0) -> #N/A | E15: =VLOOKUP(B15,'Phan mem'!$B$7:$G$1019,6,0) -> #N/A | I15: =G15&DAY(H15)&MONTH(H15)&YEAR(H15) -> 011900 | J15: =VLOOKUP(G15,'Nha may'!$B$2:$C$18,2,0) -> #N/A | K15: =B15&"-"&G15 -> -
A16: 15 | C16: =VLOOKUP(B16,'Phan mem'!$B$7:$D$1019,2,0) -> #N/A | D16: =VLOOKUP(B16,'Phan mem'!$B$7:$D$1019,3,0) -> #N/A | E16: =VLOOKUP(B16,'Phan mem'!$B$7:$G$1019,6,0) -> #N/A | I16: =G16&DAY(H16)&MONTH(H16)&YEAR(H16) -> 011900 | J16: =VLOOKUP(G16,'Nha may'!$B$2:$C$18,2,0) -> #N/A | K16: =B16&"-"&G16 -> -
A17: 16 | C17: =VLOOKUP(B17,'Phan mem'!$B$7:$D$1019,2,0) -> #N/A | D17: =VLOOKUP(B17,'Phan mem'!$B$7:$D$1019,3,0) -> #N/A | E17: =VLOOKUP(B17,'Phan mem'!$B$7:$G$1019,6,0) -> #N/A | I17: =G17&DAY(H17)&MONTH(H17)&YEAR(H17) -> 011900 | J17: =VLOOKUP(G17,'Nha may'!$B$2:$C$18,2,0) -> #N/A | K17: =B17&"-"&G17 -> -
A18: 17 | C18: =VLOOKUP(B18,'Phan mem'!$B$7:$D$1019,2,0) -> #N/A | D18: =VLOOKUP(B18,'Phan mem'!$B$7:$D$1019,3,0) -> #N/A | E18: =VLOOKUP(B18,'Phan mem'!$B$7:$G$1019,6,0) -> #N/A | I18: =G18&DAY(H18)&MONTH(H18)&YEAR(H18) -> 011900 | J18: =VLOOKUP(G18,'Nha may'!$B$2:$C$18,2) -> #N/A | K18: =B18&"-"&G18 -> -
A19: 18 | C19: =VLOOKUP(B19,'Phan mem'!$B$7:$D$1019,2,0) -> #N/A | D19: =VLOOKUP(B19,'Phan mem'!$B$7:$D$1019,3,0) -> #N/A | E19: =VLOOKUP(B19,'Phan mem'!$B$7:$G$1019,6,0) -> #N/A | I19: =G19&DAY(H19)&MONTH(H19)&YEAR(H19) -> 011900 | J19: =VLOOKUP(G19,'Nha may'!$B$2:$C$18,2) -> #N/A | K19: =B19&"-"&G19 -> -
A20: 19 | C20: =VLOOKUP(B20,'Phan mem'!$B$7:$D$1019,2,0) -> #N/A | D20: =VLOOKUP(B20,'Phan mem'!$B$7:$D$1019,3,0) -> #N/A | E20: =VLOOKUP(B20,'Phan mem'!$B$7:$G$1019,6,0) -> #N/A | I20: =G20&DAY(H20)&MONTH(H20)&YEAR(H20) -> 011900 | J20: =VLOOKUP(G20,'Nha may'!$B$2:$C$18,2) -> #N/A | K20: =B20&"-"&G20 -> -
A21: 20 | C21: =VLOOKUP(B21,'Phan mem'!$B$7:$D$1019,2,0) -> #N/A | D21: =VLOOKUP(B21,'Phan mem'!$B$7:$D$1019,3,0) -> #N/A | E21: =VLOOKUP(B21,'Phan mem'!$B$7:$G$1019,6,0) -> #N/A | I21: =G21&DAY(H21)&MONTH(H21)&YEAR(H21) -> 011900 | J21: =VLOOKUP(G21,'Nha may'!$B$2:$C$18,2) -> #N/A | K21: =B21&"-"&G21 -> -
A22: 21 | C22: =VLOOKUP(B22,'Phan mem'!$B$7:$D$1019,2,0) -> #N/A | D22: =VLOOKUP(B22,'Phan mem'!$B$7:$D$1019,3,0) -> #N/A | E22: =VLOOKUP(B22,'Phan mem'!$B$7:$G$1019,6,0) -> #N/A | I22: =G22&DAY(H22)&MONTH(H22)&YEAR(H22) -> 011900 | J22: =VLOOKUP(G22,'Nha may'!$B$2:$C$18,2) -> #N/A | K22: =B22&"-"&G22 -> -
A23: 22 | C23: =VLOOKUP(B23,'Phan mem'!$B$7:$D$1019,2,0) -> #N/A | D23: =VLOOKUP(B23,'Phan mem'!$B$7:$D$1019,3,0) -> #N/A | E23: =VLOOKUP(B23,'Phan mem'!$B$7:$G$1019,6,0) -> #N/A | I23: =G23&DAY(H23)&MONTH(H23)&YEAR(H23) -> 011900 | J23: =VLOOKUP(G23,'Nha may'!$B$2:$C$18,2) -> #N/A | K23: =B23&"-"&G23 -> -
A24: 23 | C24: =VLOOKUP(B24,'Phan mem'!$B$7:$D$1019,2,0) -> #N/A | D24: =VLOOKUP(B24,'Phan mem'!$B$7:$D$1019,3,0) -> #N/A | E24: =VLOOKUP(B24,'Phan mem'!$B$7:$G$1019,6,0) -> #N/A | I24: =G24&DAY(H24)&MONTH(H24)&YEAR(H24) -> 011900 | J24: =VLOOKUP(G24,'Nha may'!$B$2:$C$18,2) -> #N/A | K24: =B24&"-"&G24 -> -
A25: 24 | C25: =VLOOKUP(B25,'Phan mem'!$B$7:$D$1019,2,0) -> #N/A | D25: =VLOOKUP(B25,'Phan mem'!$B$7:$D$1019,3,0) -> #N/A | E25: =VLOOKUP(B25,'Phan mem'!$B$7:$G$1019,6,0) -> #N/A | I25: =G25&DAY(H25)&MONTH(H25)&YEAR(H25) -> 011900 | J25: =VLOOKUP(G25,'Nha may'!$B$2:$C$18,2) -> #N/A | K25: =B25&"-"&G25 -> -
A26: 25 | C26: =VLOOKUP(B26,'Phan mem'!$B$7:$D$1019,2,0) -> #N/A | D26: =VLOOKUP(B26,'Phan mem'!$B$7:$D$1019,3,0) -> #N/A | E26: =VLOOKUP(B26,'Phan mem'!$B$7:$G$1019,6,0) -> #N/A | I26: =G26&DAY(H26)&MONTH(H26)&YEAR(H26) -> 011900 | J26: =VLOOKUP(G26,'Nha may'!$B$2:$C$18,2) -> #N/A | K26: =B26&"-"&G26 -> -
A27: 26 | C27: =VLOOKUP(B27,'Phan mem'!$B$7:$D$1019,2,0) -> #N/A | D27: =VLOOKUP(B27,'Phan mem'!$B$7:$D$1019,3,0) -> #N/A | E27: =VLOOKUP(B27,'Phan mem'!$B$7:$G$1019,6,0) -> #N/A | I27: =G27&DAY(H27)&MONTH(H27)&YEAR(H27) -> 011900 | J27: =VLOOKUP(G27,'Nha may'!$B$2:$C$18,2) -> #N/A | K27: =B27&"-"&G27 -> -
A28: 27 | C28: =VLOOKUP(B28,'Phan mem'!$B$7:$D$1019,2,0) -> #N/A | D28: =VLOOKUP(B28,'Phan mem'!$B$7:$D$1019,3,0) -> #N/A | E28: =VLOOKUP(B28,'Phan mem'!$B$7:$G$1019,6,0) -> #N/A | I28: =G28&DAY(H28)&MONTH(H28)&YEAR(H28) -> 011900 | J28: =VLOOKUP(G28,'Nha may'!$B$2:$C$18,2) -> #N/A | K28: =B28&"-"&G28 -> -
A29: 28 | C29: =VLOOKUP(B29,'Phan mem'!$B$7:$D$1019,2,0) -> #N/A | D29: =VLOOKUP(B29,'Phan mem'!$B$7:$D$1019,3,0) -> #N/A | E29: =VLOOKUP(B29,'Phan mem'!$B$7:$G$1019,6,0) -> #N/A | I29: =G29&DAY(H29)&MONTH(H29)&YEAR(H29) -> 011900 | J29: =VLOOKUP(G29,'Nha may'!$B$2:$C$18,2) -> #N/A | K29: =B29&"-"&G29 -> -
... A45: 44 | C45: =VLOOKUP(B45,'Phan mem'!$B$7:$D$1019,2,0) -> #N/A | D45: =VLOOKUP(B45,'Phan mem'!$B$7:$D$1019,3,0) -> #N/A | E45: =VLOOKUP(B45,'Phan mem'!$B$7:$G$1019,6,0) -> #N/A | I45: =G45&DAY(H45)&MONTH(H45)&YEAR(H45) -> 011900 | J45: =VLOOKUP(G45,'Nha may'!$B$2:$C$18,2) -> #N/A | K45: =B45&"-"&G45 -> -

Sheet Nop bao cao
A1: Dữ liệu xuất lúc 8h00 ngày 12/6/2025
A2: MSSV | B2: =IFERROR(__xludf.DUMMYFUNCTION("""COMPUTED_VALUE"""),"Họ và tên") -> Họ và tên | C2: =IFERROR(__xludf.DUMMYFUNCTION("""COMPUTED_VALUE"""),"Lớp") -> Lớp | D2: Mã chuyến | E2: =IFERROR(__xludf.DUMMYFUNCTION("""COMPUTED_VALUE"""),"Tên nhà máy") -> Tên nhà máy | F2: =IFERROR(__xludf.DUMMYFUNCTION("""COMPUTED_VALUE"""),"Loại hình chuyến TQNM") -> Loại hình chuyến TQNM | G2: =IFERROR(__xludf.DUMMYFUNCTION("""COMPUTED_VALUE"""),"Hình thức tham quan nhà máy") -> Hình thức tham quan nhà máy | H2: =IFERROR(__xludf.DUMMYFUNCTION("""COMPUTED_VALUE"""),"Giảng viên hướng dẫn") -> Giảng viên hướng dẫn
A3: 2041222734 | B3: Đỗ Ngọc Ái Mỹ | C3: 13DHQTTP03 | E3: CÔNG TY CỔ PHẦN ĐẦU TƯ VÀ THƯƠNG MẠI SATORI | F3: do Trường tổ chức | G3: trực tiếp (offline) | H3: Đỗ Mai Nguyên Phương
A4: 2041222734 | B4: Đỗ Ngọc Ái Mỹ | C4: 13DHQTTP03 | E4: Công ty TNHH Ajinomoto Việt Nam - Nhà máy Long Thành | F4: do Trường tổ chức | G4: trực tuyến (online) | H4: Đỗ Mai Nguyên Phương
A5: 2041220829 | B5: Đỗ Ngọc Thuỳ Dương | C5: 13DHQTTP03 | E5: Công ty TNHH Aeon Việt Nam | F5: do Trường tổ chức | G5: trực tiếp (offline) | H5: Đỗ Mai Nguyên Phương
A6: 2041220829 | B6: Đỗ Ngọc Thuỳ Dương | C6: 13DHQTTP03 | E6: Công ty TNHH Ajinomoto Việt Nam - Nhà máy Long Thành | F6: do Trường tổ chức | G6: trực tuyến (online) | H6: Đỗ Mai Nguyên Phương
A7: 2041220829 | B7: Đỗ Ngọc Thuỳ Dương | C7: 13DHQTTP03 | E7: Công ty TNHH Yakult Việt Nam | F7: do Trường tổ chức | G7: trực tiếp (offline) | H7: Đỗ Mai Nguyên Phương
A8: 2041224117 | B8: Đỗ Như Quỳnh | C8: 13DHQTTP02 | E8: Công ty TNHH Yakult Việt Nam | F8: do Trường tổ chức | G8: trực tiếp (offline) | H8: Đỗ Mai Nguyên Phương
A9: 2041224117 | B9: Đỗ Như Quỳnh | C9: 13DHQTTP02 | E9: CHI NHÁNH CTY CP TIẾN ĐỒNG - NHÀ MÁY BIA VINAKEN | F9: tự do | G9: trực tiếp (offline) | H9: Đỗ Mai Nguyên Phương
A10: 2041224117 | B10: Đỗ Như Quỳnh | C10: 13DHQTTP02 | E10: Công ty TNHH Ajinomoto Việt Nam - Nhà máy Long Thành | F10: do Trường tổ chức | G10: trực tuyến (online) | H10: Đỗ Mai Nguyên Phương
A11: 2041225111 | B11: Đỗ Thị Bích Thủy | C11: 13DHQTTP03 | E11: Công ty TNHH Yakult Việt Nam | F11: do Trường tổ chức | G11: trực tiếp (offline) | H11: Đỗ Mai Nguyên Phương
A12: 2041225111 | B12: Đỗ Thị Bích Thủy | C12: 13DHQTTP03 | E12: Công ty TNHH Ajinomoto Việt Nam - Nhà máy Long Thành | F12: do Trường tổ chức | G12: trực tuyến (online) | H12: Đỗ Mai Nguyên Phương
A13: 2041225111 | B13: Đỗ Thị Bích Thủy | C13: 13DHQTTP03 | E13: Công ty CP Acecook Việt Nam | F13: do Trường tổ chức | G13: trực tiếp (offline) | H13: Đỗ Mai Nguyên Phương
A14: 2041222515 | B14: Hồ Hải Lưu | C14: 13DHQTTP03 | E14: Công ty CP Acecook Việt Nam | F14: do Trường tổ chức | G14: trực tiếp (offline) | H14: Đỗ Mai Nguyên Phương
... A743: 2041224495 | B743: Nguyễn Thanh Tú | C743: 13DHQTTP03 | E743: Công ty TNHH Kewpie Việt Nam | F743: do Trường tổ chức | G743: trực tiếp (offline) | H743: Huỳnh Thị Lê Dung
A744: 2041224495 | B744: Nguyễn Thanh Tú | C744: 2041224495 | E744: Công ty TNHH Ajinomoto Việt Nam - Nhà máy Long Thành | F744: do Trường tổ chức | G744: trực tuyến (online) | H744: Huỳnh Thị Lê Dung
A745: 2041221449 | B745: Nguyễn Thị Hoa | C745: 13DHQTTP04 | E745: Công ty CP Acecook Việt Nam | F745: do Trường tổ chức | G745: trực tiếp (offline) | H745: Huỳnh Thị Lê Dung
A746: 2041221449 | B746: Nguyễn Thị Hoa | C746: 13DHQTTP04 | E746: Công ty TNHH Yakult Việt Nam | F746: do Trường tổ chức | G746: trực tiếp (offline) | H746: Huỳnh Thị Lê Dung
A747: 2041226245 | B747: Nguyễn Thị Ngọc Trăm | C747: 13DHQTTP04 | E747: Công ty TNHH Aeon Việt Nam | F747: do Trường tổ chức | G747: trực tiếp (offline) | H747: Huỳnh Thị Lê Dung
A748: 2041226245 | B748: Nguyễn Thị Ngọc Trăm | C748: 13DHQTTP04 | E748: Công ty TNHH Yakult Việt Nam | F748: do Trường tổ chức | G748: trực tiếp (offline) | H748: Huỳnh Thị Lê Dung
A749: 2041226245 | B749: Nguyễn Thị Ngọc Trăm | C749: 13DHQTTP04 | E749: Công ty TNHH Ajinomoto Việt Nam - Nhà máy Long Thành | F749: do Trường tổ chức | G749: trực tuyến (online) | H749: Huỳnh Thị Lê Dung
A750: 2041224116 | B750: Nguyễn Thị Như Quỳnh | C750: 13DHQTTP04 | E750: Công ty TNHH Yakult Việt Nam | F750: do Trường tổ chức | G750: trực tiếp (offline) | H750: Huỳnh Thị Lê Dung
A751: 2041224116 | B751: Nguyễn Thị Như Quỳnh | C751: 13DHQTTP04 | E751: CÔNG TY CỔ PHẦN ĐẦU TƯ VÀ THƯƠNG MẠI SATORI | F751: do Trường tổ chức | G751: trực tiếp (offline) | H751: Huỳnh Thị Lê Dung
A752: 2041224116 | B752: Nguyễn Thị Như Quỳnh | C752: 13DHQTTP04 | E752: Công ty TNHH Ajinomoto Việt Nam - Nhà máy Long Thành | F752: do Trường tổ chức | G752: trực tuyến (online) | H752: Huỳnh Thị Lê Dung
A753: 2041224139 | B753: Nguyễn Thị Thang Sang | C753: 13DHQTTP04 | E753: Công ty TNHH Yakult Việt Nam | F753: do Trường tổ chức | G753: trực tiếp (offline) | H753: Huỳnh Thị Lê Dung
A754: 2041224139 | B754: Nguyễn Thị Thanh Sang | C754: 13DHQTTP04 | E754: Công ty TNHH Aeon Việt Nam | F754: do Trường tổ chức | G754: trực tiếp (offline) | H754: Huỳnh Thị Lê Dung
A755: 2041224139 | B755: Nguyễn Thị Thanh Sang | C755: 13DHQTTP04 | E755: Công ty TNHH Yakult Việt Nam | F755: do Trường tổ chức | G755: trực tiếp (offline) | H755: Huỳnh Thị Lê Dung
A756: 2041224139 | B756: Nguyễn Thị Thanh Sang | C756: 13DHQTTP04 | E756: Công ty TNHH Ajinomoto Việt Nam - Nhà máy Biên Hòa | F756: do Trường tổ chức | G756: trực tuyến (online) | H756: Huỳnh Thị Lê Dung
... A1993: 2005230180 | B1993: Vũ Quốc Hoàng | C1993: 14DHTP04 | E1993: CHI NHÁNH CTY CP TIẾN ĐỒNG - NHÀ MÁY BIA VINAKEN | F1993: do Trường tổ chức | G1993: trực tiếp (offline) | H1993: Vũ Thị Hường

Sheet Ket qua duyet
A4: PHÂN CÔNG SINH VIÊN THỰC HIỆN HỌC PHẦN KIẾN TẬP
P5: Nhà máy 1 | X5: Nhà máy 2 | AF5: Nhà máy 3 | AN5: Nhà máy 4 (Nhà máy online) | AV5: Nhà máy 5 (Nhà máy online)
A6: STT | B6: Mã HS-SV | C6: Họ đệm | D6: Tên | E6: Giới tính | F6: Ngày sinh | G6: Lớp học | H6: Giảng viên Hướng dẫn | I6: Kết quả | J6: Điểm tổng kết | K6: Đủ điều kiện NM | L6: Số NM đã đi (không trùng) | M6: Số NM off | N6: Số NM onl | O6: Số NM trùng | P6: Tên NM | Q6: Ngày TQNM | R6: Hình thức đi | S6: Điểm chuẩn bị | T6: Điểm thưởng | U6: Điểm bài báo cáo | V6: Điểm vấn đáp | W6: Điểm TB | X6: Tên NM | Y6: Ngày TQNM | Z6: Hình thức đi | AA6: Điểm chuẩn bị | AB6: Điểm thưởng | AC6: Điểm bài báo cáo | AD6: Điểm vấn đáp | AE6: Điểm TB | AF6: Tên NM | AG6: Ngày TQNM | AH6: Hình thức đi | AI6: Điểm chuẩn bị | AJ6: Điểm thưởng | AK6: Điểm bài báo cáo | AL6: Điểm vấn đáp | AM6: Điểm TB | AN6: Tên NM | AO6: Ngày TQNM | AP6: Hình thức đi | AQ6: Điểm chuẩn bị | AR6: Điểm thưởng | AS6: Điểm bài báo cáo | AT6: Điểm vấn đáp | AU6: Điểm TB | AV6: Tên NM | AW6: Ngày TQNM | AX6: Hình thức đi | AY6: Điểm chuẩn bị | AZ6: Điểm thưởng | BA6: Điểm bài báo cáo | BB6: Điểm vấn đáp | BC6: Điểm TB
A7: 1 | B7: 2005230599 | C7: Lê Thị Thu | D7: Trang | F7: 24/05/2005 | G7: 14DHTP07 | H7: Đào Thị Tuyết Mai | I7: =IF(AND(J7>=4,K7="Đủ"), "Đậu", "Không đậu") -> Không đậu | K7: =IF(AND(L7>=3,M7>=2),"Đủ","Không đủ") -> Không đủ | L7: =M7+N7-O7 -> 0 | M7: {=SUMPRODUCT(--(LEN(CHOOSE({1,2,3},P7,X7,AF7))>0))} -> 0 | N7: {=SUMPRODUCT(--(LEN(CHOOSE({1,2},AN7,AV7))>0))} -> 0 | O7: =(IF(P7<>"",P7=X7,0)) +(IF(P7<>"",P7=AF7,0)) +(IF(P7<>"",P7=AN7,0)) +(IF(P7<>"",P7=AV7,0)) +(IF(X7<>"",X7=AF7,0)) +(IF(X7<>"",X7=AN7,0)) +(IF(X7<>"",X7=AV7,0)) +(IF(AF7<>"",AF7=AN7,0)) +(IF(AF7<>"",AF7=AV7,0)) +(IF(AN7<>"",AN7=AV7,0)) -> 0 | P7: {=IFERROR(INDEX(_xlfn._xlws.FILTER('Dang ky_off'!$J$4:$J$4000,'Dang ky_off'!$B$4:$B$4000=$B7),1),"")} | Q7: {=IFERROR(INDEX(_xlfn._xlws.FILTER('Dang ky_off'!$H$4:$H$4000,'Dang ky_off'!$B$4:$B$4000=$B7),1),"")} | R7: trực tiếp (offline) | S7: {=IFERROR(INDEX(_xlfn._xlws.FILTER('Dang ky_off'!$L$4:$L$4000,'Dang ky_off'!$B$4:$B$4000=$B7),1),"")} | T7: {=IFERROR(INDEX(_xlfn._xlws.FILTER('Dang ky_off'!$M$4:$M$4000,'Dang ky_off'!$B$4:$B$4000=$B7),1),"")} | W7: =ROUND(MIN(S7*0.3+U7*0.3+V7*0.4+T7,10),1) -> #VALUE! | X7: {=IFERROR(INDEX(_xlfn._xlws.FILTER('Dang ky_off'!$J$4:$J$4000,'Dang ky_off'!$B$4:$B$4000=$B7),2),"")} | Y7: {=IFERROR(INDEX(_xlfn._xlws.FILTER('Dang ky_off'!$H$4:$H$4000,'Dang ky_off'!$B$4:$B$4000=$B7),2),"")} | Z7: trực tiếp (offline) | AA7: {=IFERROR(INDEX(_xlfn._xlws.FILTER('Dang ky_off'!$L$4:$L$4000,'Dang ky_off'!$B$4:$B$4000=$B7),2),"")} | AB7: {=IFERROR(INDEX(_xlfn._xlws.FILTER('Dang ky_off'!$M$4:$M$4000,'Dang ky_off'!$B$4:$B$4000=$B7),2),"")} | AE7: =ROUND(MIN(AA7*0.3+AC7*0.3+AD7*0.4+AB7,10),1) -> #VALUE! | AF7: {=IFERROR(INDEX(_xlfn._xlws.FILTER('Dang ky_off'!$J$4:$J$4000,'Dang ky_off'!$B$4:$B$4000=$B7),3),"")} | AG7: {=IFERROR(INDEX(_xlfn._xlws.FILTER('Dang ky_off'!$H$4:$H$4000,'Dang ky_off'!$B$4:$B$4000=$B7),3),"")} | AH7: trực tiếp (offline) | AI7: {=IFERROR(INDEX(_xlfn._xlws.FILTER('Dang ky_off'!$L$4:$L$4000,'Dang ky_off'!$B$4:$B$4000=$B7),3),"")} | AJ7: {=IFERROR(INDEX(_xlfn._xlws.FILTER('Dang ky_off'!$M$4:$M$4000,'Dang ky_off'!$B$4:$B$4000=$B7),3),"")} | AM7: =ROUND(MIN(AI7*0.3+AK7*0.3+AL7*0.4+AJ7,10),1) -> #VALUE! | AN7: {=IFERROR(INDEX(_xlfn._xlws.FILTER('Dang ky_onl'!$J$6:$J$4000,'Dang ky_onl'!$B$6:$B$4000=$B7),1),"")} | AO7: {=IFERROR(INDEX(_xlfn._xlws.FILTER('Dang ky_onl'!$H$6:$H$4000,'Dang ky_onl'!$B$6:$B$4000=$B7),1),"")} | AP7: trực tuyến (online) | AQ7: {=IFERROR(INDEX(_xlfn._xlws.FILTER('Dang ky_onl'!$L$6:$L$4000,'Dang ky_onl'!$B$6:$B$4000=$B7),1),"")} | AR7: {=IFERROR(INDEX(_xlfn._xlws.FILTER('Dang ky_onl'!$M$6:$M$4000,'Dang ky_onl'!$B$6:$B$4000=$B7),1),"")} | AU7: =ROUND(MIN(AQ7*0.3+AS7*0.3+AT7*0.4+AR7,10),1) -> #VALUE! | AV7: {=IFERROR(INDEX(_xlfn._xlws.FILTER('Dang ky_onl'!$J$6:$J$4000,'Dang ky_onl'!$B$6:$B$4000=$B7),2),"")} | AW7: {=IFERROR(INDEX(_xlfn._xlws.FILTER('Dang ky_onl'!$H$6:$H$4000,'Dang ky_onl'!$B$6:$B$4000=$B7),2),"")} | AX7: trực tuyến (online) | AY7: {=IFERROR(INDEX(_xlfn._xlws.FILTER('Dang ky_onl'!$L$6:$L$4000,'Dang ky_onl'!$B$6:$B$4000=$B7),2),"")} | AZ7: {=IFERROR(INDEX(_xlfn._xlws.FILTER('Dang ky_onl'!$M$6:$M$4000,'Dang ky_onl'!$B$6:$B$4000=$B7),2),"")} | BC7: =ROUND(MIN(AY7*0.3+BA7*0.3+BB7*0.4+AZ7,10),1) -> #VALUE!
A8: 2 | B8: 2005230601 | C8: Nguyễn Ngọc | D8: Trang | F8: 02/08/2005 | G8: 14DHTP07 | H8: Đào Thị Tuyết Mai | I8: =IF(AND(J8>=4,K8="Đủ"), "Đậu", "Không đậu") -> Không đậu | K8: =IF(AND(L8>=3,M8>=2),"Đủ","Không đủ") -> Không đủ | L8: =M8+N8-O8 -> 1 | M8: {=SUMPRODUCT(--(LEN(CHOOSE({1,2,3},P8,X8,AF8))>0))} -> 1 | N8: {=SUMPRODUCT(--(LEN(CHOOSE({1,2},AN8,AV8))>0))} -> 0 | O8: =(IF(P8<>"",P8=X8,0)) +(IF(P8<>"",P8=AF8,0)) +(IF(P8<>"",P8=AN8,0)) +(IF(P8<>"",P8=AV8,0)) +(IF(X8<>"",X8=AF8,0)) +(IF(X8<>"",X8=AN8,0)) +(IF(X8<>"",X8=AV8,0)) +(IF(AF8<>"",AF8=AN8,0)) +(IF(AF8<>"",AF8=AV8,0)) +(IF(AN8<>"",AN8=AV8,0)) -> 0 | P8: {=IFERROR(INDEX(_xlfn._xlws.FILTER('Dang ky_off'!$J$4:$J$4000,'Dang ky_off'!$B$4:$B$4000=$B8),1),"")} -> Công ty TNHH Yakult Việt Nam | Q8: {=IFERROR(INDEX(_xlfn._xlws.FILTER('Dang ky_off'!$H$4:$H$4000,'Dang ky_off'!$B$4:$B$4000=$B8),1),"")} -> 46022 | R8: trực tiếp (offline) | S8: {=IFERROR(INDEX(_xlfn._xlws.FILTER('Dang ky_off'!$L$4:$L$4000,'Dang ky_off'!$B$4:$B$4000=$B8),1),"")} -> 9.5 | T8: {=IFERROR(INDEX(_xlfn._xlws.FILTER('Dang ky_off'!$M$4:$M$4000,'Dang ky_off'!$B$4:$B$4000=$B8),1),"")} -> 0 | W8: =ROUND(MIN(S8*0.3+U8*0.3+V8*0.4+T8,10),1) -> 2.9 | X8: {=IFERROR(INDEX(_xlfn._xlws.FILTER('Dang ky_off'!$J$4:$J$4000,'Dang ky_off'!$B$4:$B$4000=$B8),2),"")} | Y8: {=IFERROR(INDEX(_xlfn._xlws.FILTER('Dang ky_off'!$H$4:$H$4000,'Dang ky_off'!$B$4:$B$4000=$B8),2),"")} | Z8: trực tiếp (offline) | AA8: {=IFERROR(INDEX(_xlfn._xlws.FILTER('Dang ky_off'!$L$4:$L$4000,'Dang ky_off'!$B$4:$B$4000=$B8),2),"")} | AB8: {=IFERROR(INDEX(_xlfn._xlws.FILTER('Dang ky_off'!$M$4:$M$4000,'Dang ky_off'!$B$4:$B$4000=$B8),2),"")} | AE8: =ROUND(MIN(AA8*0.3+AC8*0.3+AD8*0.4+AB8,10),1) -> #VALUE! | AF8: {=IFERROR(INDEX(_xlfn._xlws.FILTER('Dang ky_off'!$J$4:$J$43,'Dang ky_off'!$B$4:$B$43=$B8),3),"")} | AG8: {=IFERROR(INDEX(_xlfn._xlws.FILTER('Dang ky_off'!$H$4:$H$43,'Dang ky_off'!$B$4:$B$43=$B8),3),"")} | AH8: trực tiếp (offline) | AI8: {=IFERROR(INDEX(_xlfn._xlws.FILTER('Dang ky_off'!$L$4:$L$43,'Dang ky_off'!$B$4:$B$43=$B8),3),"")} | AJ8: {=IFERROR(INDEX(_xlfn._xlws.FILTER('Dang ky_off'!$M$4:$M$43,'Dang ky_off'!$B$4:$B$43=$B8),3),"")} | AM8: =ROUND(MIN(AI8*0.3+AK8*0.3+AL8*0.4+AJ8,10),1) -> #VALUE! | AN8: {=IFERROR(INDEX(_xlfn._xlws.FILTER('Dang ky_onl'!$J$6:$J$4000,'Dang ky_onl'!$B$6:$B$4000=$B8),1),"")} | AO8: {=IFERROR(INDEX(_xlfn._xlws.FILTER('Dang ky_onl'!$H$6:$H$4000,'Dang ky_onl'!$B$6:$B$4000=$B8),1),"")} | AP8: trực tuyến (online) | AQ8: {=IFERROR(INDEX(_xlfn._xlws.FILTER('Dang ky_onl'!$L$6:$L$4000,'Dang ky_onl'!$B$6:$B$4000=$B8),1),"")} | AR8: {=IFERROR(INDEX(_xlfn._xlws.FILTER('Dang ky_onl'!$M$6:$M$4000,'Dang ky_onl'!$B$6:$B$4000=$B8),1),"")} | AU8: =ROUND(MIN(AQ8*0.3+AS8*0.3+AT8*0.4+AR8,10),1) -> #VALUE! | AV8: {=IFERROR(INDEX(_xlfn._xlws.FILTER('Dang ky_onl'!$J$6:$J$4000,'Dang ky_onl'!$B$6:$B$4000=$B8),2),"")} | AW8: {=IFERROR(INDEX(_xlfn._xlws.FILTER('Dang ky_onl'!$H$6:$H$4000,'Dang ky_onl'!$B$6:$B$4000=$B8),2),"")} | AX8: trực tuyến (online) | AY8: {=IFERROR(INDEX(_xlfn._xlws.FILTER('Dang ky_onl'!$L$6:$L$4000,'Dang ky_onl'!$B$6:$B$4000=$B8),2),"")} | AZ8: {=IFERROR(INDEX(_xlfn._xlws.FILTER('Dang ky_onl'!$M$6:$M$4000,'Dang ky_onl'!$B$6:$B$4000=$B8),2),"")} | BC8: =ROUND(MIN(AY8*0.3+BA8*0.3+BB8*0.4+AZ8,10),1) -> #VALUE!
A9: 3 | B9: 2005230593 | C9: Trịnh Huyền | D9: Trang | F9: 21/02/2005 | G9: 14DHTP07 | H9: Đào Thị Tuyết Mai | I9: =IF(AND(J9>=4,K9="Đủ"), "Đậu", "Không đậu") -> Không đậu | K9: =IF(AND(L9>=3,M9>=2),"Đủ","Không đủ") -> Không đủ | L9: =M9+N9-O9 -> 0 | M9: {=SUMPRODUCT(--(LEN(CHOOSE({1,2,3},P9,X9,AF9))>0))} -> 0 | N9: {=SUMPRODUCT(--(LEN(CHOOSE({1,2},AN9,AV9))>0))} -> 0 | O9: =(IF(P9<>"",P9=X9,0)) +(IF(P9<>"",P9=AF9,0)) +(IF(P9<>"",P9=AN9,0)) +(IF(P9<>"",P9=AV9,0)) +(IF(X9<>"",X9=AF9,0)) +(IF(X9<>"",X9=AN9,0)) +(IF(X9<>"",X9=AV9,0)) +(IF(AF9<>"",AF9=AN9,0)) +(IF(AF9<>"",AF9=AV9,0)) +(IF(AN9<>"",AN9=AV9,0)) -> 0 | P9: {=IFERROR(INDEX(_xlfn._xlws.FILTER('Dang ky_off'!$J$4:$J$4000,'Dang ky_off'!$B$4:$B$4000=$B9),1),"")} | Q9: {=IFERROR(INDEX(_xlfn._xlws.FILTER('Dang ky_off'!$H$4:$H$4000,'Dang ky_off'!$B$4:$B$4000=$B9),1),"")} | R9: trực tiếp (offline) | S9: {=IFERROR(INDEX(_xlfn._xlws.FILTER('Dang ky_off'!$L$4:$L$4000,'Dang ky_off'!$B$4:$B$4000=$B9),1),"")} | T9: {=IFERROR(INDEX(_xlfn._xlws.FILTER('Dang ky_off'!$M$4:$M$4000,'Dang ky_off'!$B$4:$B$4000=$B9),1),"")} | W9: =ROUND(MIN(S9*0.3+U9*0.3+V9*0.4+T9,10),1) -> #VALUE! | X9: {=IFERROR(INDEX(_xlfn._xlws.FILTER('Dang ky_off'!$J$4:$J$4000,'Dang ky_off'!$B$4:$B$4000=$B9),2),"")} | Y9: {=IFERROR(INDEX(_xlfn._xlws.FILTER('Dang ky_off'!$H$4:$H$4000,'Dang ky_off'!$B$4:$B$4000=$B9),2),"")} | Z9: trực tiếp (offline) | AA9: {=IFERROR(INDEX(_xlfn._xlws.FILTER('Dang ky_off'!$L$4:$L$4000,'Dang ky_off'!$B$4:$B$4000=$B9),2),"")} | AB9: {=IFERROR(INDEX(_xlfn._xlws.FILTER('Dang ky_off'!$M$4:$M$4000,'Dang ky_off'!$B$4:$B$4000=$B9),2),"")} | AE9: =ROUND(MIN(AA9*0.3+AC9*0.3+AD9*0.4+AB9,10),1) -> #VALUE! | AF9: {=IFERROR(INDEX(_xlfn._xlws.FILTER('Dang ky_off'!$J$4:$J$43,'Dang ky_off'!$B$4:$B$43=$B9),3),"")} | AG9: {=IFERROR(INDEX(_xlfn._xlws.FILTER('Dang ky_off'!$H$4:$H$43,'Dang ky_off'!$B$4:$B$43=$B9),3),"")} | AH9: trực tiếp (offline) | AI9: {=IFERROR(INDEX(_xlfn._xlws.FILTER('Dang ky_off'!$L$4:$L$43,'Dang ky_off'!$B$4:$B$43=$B9),3),"")} | AJ9: {=IFERROR(INDEX(_xlfn._xlws.FILTER('Dang ky_off'!$M$4:$M$43,'Dang ky_off'!$B$4:$B$43=$B9),3),"")} | AM9: =ROUND(MIN(AI9*0.3+AK9*0.3+AL9*0.4+AJ9,10),1) -> #VALUE! | AN9: {=IFERROR(INDEX(_xlfn._xlws.FILTER('Dang ky_onl'!$J$6:$J$4000,'Dang ky_onl'!$B$6:$B$4000=$B9),1),"")} | AO9: {=IFERROR(INDEX(_xlfn._xlws.FILTER('Dang ky_onl'!$H$6:$H$4000,'Dang ky_onl'!$B$6:$B$4000=$B9),1),"")} | AP9: trực tuyến (online) | AQ9: {=IFERROR(INDEX(_xlfn._xlws.FILTER('Dang ky_onl'!$L$6:$L$4000,'Dang ky_onl'!$B$6:$B$4000=$B9),1),"")} | AR9: {=IFERROR(INDEX(_xlfn._xlws.FILTER('Dang ky_onl'!$M$6:$M$4000,'Dang ky_onl'!$B$6:$B$4000=$B9),1),"")} | AU9: =ROUND(MIN(AQ9*0.3+AS9*0.3+AT9*0.4+AR9,10),1) -> #VALUE! | AV9: {=IFERROR(INDEX(_xlfn._xlws.FILTER('Dang ky_onl'!$J$6:$J$4000,'Dang ky_onl'!$B$6:$B$4000=$B9),2),"")} | AW9: {=IFERROR(INDEX(_xlfn._xlws.FILTER('Dang ky_onl'!$H$6:$H$4000,'Dang ky_onl'!$B$6:$B$4000=$B9),2),"")} | AX9: trực tuyến (online) | AY9: {=IFERROR(INDEX(_xlfn._xlws.FILTER('Dang ky_onl'!$L$6:$L$4000,'Dang ky_onl'!$B$6:$B$4000=$B9),2),"")} | AZ9: {=IFERROR(INDEX(_xlfn._xlws.FILTER('Dang ky_onl'!$M$6:$M$4000,'Dang ky_onl'!$B$6:$B$4000=$B9),2),"")} | BC9: =ROUND(MIN(AY9*0.3+BA9*0.3+BB9*0.4+AZ9,10),1) -> #VALUE!
A10: 4 | B10: 2005230619 | C10: Trần Thị Quế | D10: Trân | F10: 10/03/2005 | G10: 14DHTP07 | H10: Đào Thị Tuyết Mai | I10: =IF(AND(J10>=4,K10="Đủ"), "Đậu", "Không đậu") -> Không đậu | K10: =IF(AND(L10>=3,M10>=2),"Đủ","Không đủ") -> Không đủ | L10: =M10+N10-O10 -> 1 | M10: {=SUMPRODUCT(--(LEN(CHOOSE({1,2,3},P10,X10,AF10))>0))} -> 1 | N10: {=SUMPRODUCT(--(LEN(CHOOSE({1,2},AN10,AV10))>0))} -> 0 | O10: =(IF(P10<>"",P10=X10,0)) +(IF(P10<>"",P10=AF10,0)) +(IF(P10<>"",P10=AN10,0)) +(IF(P10<>"",P10=AV10,0)) +(IF(X10<>"",X10=AF10,0)) +(IF(X10<>"",X10=AN10,0)) +(IF(X10<>"",X10=AV10,0)) +(IF(AF10<>"",AF10=AN10,0)) +(IF(AF10<>"",AF10=AV10,0)) +(IF(AN10<>"",AN10=AV10,0)) -> 0 | P10: {=IFERROR(INDEX(_xlfn._xlws.FILTER('Dang ky_off'!$J$4:$J$4000,'Dang ky_off'!$B$4:$B$4000=$B10),1),"")} -> Công ty TNHH Yakult Việt Nam | Q10: {=IFERROR(INDEX(_xlfn._xlws.FILTER('Dang ky_off'!$H$4:$H$4000,'Dang ky_off'!$B$4:$B$4000=$B10),1),"")} -> 46022 | R10: trực tiếp (offline) | S10: {=IFERROR(INDEX(_xlfn._xlws.FILTER('Dang ky_off'!$L$4:$L$4000,'Dang ky_off'!$B$4:$B$4000=$B10),1),"")} -> 10 | T10: {=IFERROR(INDEX(_xlfn._xlws.FILTER('Dang ky_off'!$M$4:$M$4000,'Dang ky_off'!$B$4:$B$4000=$B10),1),"")} -> 0.5 | W10: =ROUND(MIN(S10*0.3+U10*0.3+V10*0.4+T10,10),1) -> 3.5 | X10: {=IFERROR(INDEX(_xlfn._xlws.FILTER('Dang ky_off'!$J$4:$J$4000,'Dang ky_off'!$B$4:$B$4000=$B10),2),"")} | Y10: {=IFERROR(INDEX(_xlfn._xlws.FILTER('Dang ky_off'!$H$4:$H$4000,'Dang ky_off'!$B$4:$B$4000=$B10),2),"")} | Z10: trực tiếp (offline) | AA10: {=IFERROR(INDEX(_xlfn._xlws.FILTER('Dang ky_off'!$L$4:$L$4000,'Dang ky_off'!$B$4:$B$4000=$B10),2),"")} | AB10: {=IFERROR(INDEX(_xlfn._xlws.FILTER('Dang ky_off'!$M$4:$M$4000,'Dang ky_off'!$B$4:$B$4000=$B10),2),"")} | AE10: =ROUND(MIN(AA10*0.3+AC10*0.3+AD10*0.4+AB10,10),1) -> #VALUE! | AF10: {=IFERROR(INDEX(_xlfn._xlws.FILTER('Dang ky_off'!$J$4:$J$43,'Dang ky_off'!$B$4:$B$43=$B10),3),"")} | AG10: {=IFERROR(INDEX(_xlfn._xlws.FILTER('Dang ky_off'!$H$4:$H$43,'Dang ky_off'!$B$4:$B$43=$B10),3),"")} | AH10: trực tiếp (offline) | AI10: {=IFERROR(INDEX(_xlfn._xlws.FILTER('Dang ky_off'!$L$4:$L$43,'Dang ky_off'!$B$4:$B$43=$B10),3),"")} | AJ10: {=IFERROR(INDEX(_xlfn._xlws.FILTER('Dang ky_off'!$M$4:$M$43,'Dang ky_off'!$B$4:$B$43=$B10),3),"")} | AM10: =ROUND(MIN(AI10*0.3+AK10*0.3+AL10*0.4+AJ10,10),1) -> #VALUE! | AN10: {=IFERROR(INDEX(_xlfn._xlws.FILTER('Dang ky_onl'!$J$6:$J$4000,'Dang ky_onl'!$B$6:$B$4000=$B10),1),"")} | AO10: {=IFERROR(INDEX(_xlfn._xlws.FILTER('Dang ky_onl'!$H$6:$H$4000,'Dang ky_onl'!$B$6:$B$4000=$B10),1),"")} | AP10: trực tuyến (online) | AQ10: {=IFERROR(INDEX(_xlfn._xlws.FILTER('Dang ky_onl'!$L$6:$L$4000,'Dang ky_onl'!$B$6:$B$4000=$B10),1),"")} | AR10: {=IFERROR(INDEX(_xlfn._xlws.FILTER('Dang ky_onl'!$M$6:$M$4000,'Dang ky_onl'!$B$6:$B$4000=$B10),1),"")} | AU10: =ROUND(MIN(AQ10*0.3+AS10*0.3+AT10*0.4+AR10,10),1) -> #VALUE! | AV10: {=IFERROR(INDEX(_xlfn._xlws.FILTER('Dang ky_onl'!$J$6:$J$4000,'Dang ky_onl'!$B$6:$B$4000=$B10),2),"")} | AW10: {=IFERROR(INDEX(_xlfn._xlws.FILTER('Dang ky_onl'!$H$6:$H$4000,'Dang ky_onl'!$B$6:$B$4000=$B10),2),"")} | AX10: trực tuyến (online) | AY10: {=IFERROR(INDEX(_xlfn._xlws.FILTER('Dang ky_onl'!$L$6:$L$4000,'Dang ky_onl'!$B$6:$B$4000=$B10),2),"")} | AZ10: {=IFERROR(INDEX(_xlfn._xlws.FILTER('Dang ky_onl'!$M$6:$M$4000,'Dang ky_onl'!$B$6:$B$4000=$B10),2),"")} | BC10: =ROUND(MIN(AY10*0.3+BA10*0.3+BB10*0.4+AZ10,10),1) -> #VALUE!
A11: 5 | B11: 2005230643 | C11: Tiêu Lam | D11: Trường | F11: 27/09/2005 | G11: 14DHTP07 | H11: Đào Thị Tuyết Mai | I11: =IF(AND(J11>=4,K11="Đủ"), "Đậu", "Không đậu") -> Không đậu | K11: =IF(AND(L11>=3,M11>=2),"Đủ","Không đủ") -> Không đủ | L11: =M11+N11-O11 -> 0 | M11: {=SUMPRODUCT(--(LEN(CHOOSE({1,2,3},P11,X11,AF11))>0))} -> 0 | N11: {=SUMPRODUCT(--(LEN(CHOOSE({1,2},AN11,AV11))>0))} -> 0 | O11: =(IF(P11<>"",P11=X11,0)) +(IF(P11<>"",P11=AF11,0)) +(IF(P11<>"",P11=AN11,0)) +(IF(P11<>"",P11=AV11,0)) +(IF(X11<>"",X11=AF11,0)) +(IF(X11<>"",X11=AN11,0)) +(IF(X11<>"",X11=AV11,0)) +(IF(AF11<>"",AF11=AN11,0)) +(IF(AF11<>"",AF11=AV11,0)) +(IF(AN11<>"",AN11=AV11,0)) -> 0 | P11: {=IFERROR(INDEX(_xlfn._xlws.FILTER('Dang ky_off'!$J$4:$J$4000,'Dang ky_off'!$B$4:$B$4000=$B11),1),"")} | Q11: {=IFERROR(INDEX(_xlfn._xlws.FILTER('Dang ky_off'!$H$4:$H$4000,'Dang ky_off'!$B$4:$B$4000=$B11),1),"")} | R11: trực tiếp (offline) | S11: {=IFERROR(INDEX(_xlfn._xlws.FILTER('Dang ky_off'!$L$4:$L$4000,'Dang ky_off'!$B$4:$B$4000=$B11),1),"")} | T11: {=IFERROR(INDEX(_xlfn._xlws.FILTER('Dang ky_off'!$M$4:$M$4000,'Dang ky_off'!$B$4:$B$4000=$B11),1),"")} | W11: =ROUND(MIN(S11*0.3+U11*0.3+V11*0.4+T11,10),1) -> #VALUE! | X11: {=IFERROR(INDEX(_xlfn._xlws.FILTER('Dang ky_off'!$J$4:$J$4000,'Dang ky_off'!$B$4:$B$4000=$B11),2),"")} | Y11: {=IFERROR(INDEX(_xlfn._xlws.FILTER('Dang ky_off'!$H$4:$H$4000,'Dang ky_off'!$B$4:$B$4000=$B11),2),"")} | Z11: trực tiếp (offline) | AA11: {=IFERROR(INDEX(_xlfn._xlws.FILTER('Dang ky_off'!$L$4:$L$4000,'Dang ky_off'!$B$4:$B$4000=$B11),2),"")} | AB11: {=IFERROR(INDEX(_xlfn._xlws.FILTER('Dang ky_off'!$M$4:$M$4000,'Dang ky_off'!$B$4:$B$4000=$B11),2),"")} | AE11: =ROUND(MIN(AA11*0.3+AC11*0.3+AD11*0.4+AB11,10),1) -> #VALUE! | AF11: {=IFERROR(INDEX(_xlfn._xlws.FILTER('Dang ky_off'!$J$4:$J$43,'Dang ky_off'!$B$4:$B$43=$B11),3),"")} | AG11: {=IFERROR(INDEX(_xlfn._xlws.FILTER('Dang ky_off'!$H$4:$H$43,'Dang ky_off'!$B$4:$B$43=$B11),3),"")} | AH11: trực tiếp (offline) | AI11: {=IFERROR(INDEX(_xlfn._xlws.FILTER('Dang ky_off'!$L$4:$L$43,'Dang ky_off'!$B$4:$B$43=$B11),3),"")} | AJ11: {=IFERROR(INDEX(_xlfn._xlws.FILTER('Dang ky_off'!$M$4:$M$43,'Dang ky_off'!$B$4:$B$43=$B11),3),"")} | AM11: =ROUND(MIN(AI11*0.3+AK11*0.3+AL11*0.4+AJ11,10),1) -> #VALUE! | AN11: {=IFERROR(INDEX(_xlfn._xlws.FILTER('Dang ky_onl'!$J$6:$J$4000,'Dang ky_onl'!$B$6:$B$4000=$B11),1),"")} | AO11: {=IFERROR(INDEX(_xlfn._xlws.FILTER('Dang ky_onl'!$H$6:$H$4000,'Dang ky_onl'!$B$6:$B$4000=$B11),1),"")} | AP11: trực tuyến (online) | AQ11: {=IFERROR(INDEX(_xlfn._xlws.FILTER('Dang ky_onl'!$L$6:$L$4000,'Dang ky_onl'!$B$6:$B$4000=$B11),1),"")} | AR11: {=IFERROR(INDEX(_xlfn._xlws.FILTER('Dang ky_onl'!$M$6:$M$4000,'Dang ky_onl'!$B$6:$B$4000=$B11),1),"")} | AU11: =ROUND(MIN(AQ11*0.3+AS11*0.3+AT11*0.4+AR11,10),1) -> #VALUE! | AV11: {=IFERROR(INDEX(_xlfn._xlws.FILTER('Dang ky_onl'!$J$6:$J$4000,'Dang ky_onl'!$B$6:$B$4000=$B11),2),"")} | AW11: {=IFERROR(INDEX(_xlfn._xlws.FILTER('Dang ky_onl'!$H$6:$H$4000,'Dang ky_onl'!$B$6:$B$4000=$B11),2),"")} | AX11: trực tuyến (online) | AY11: {=IFERROR(INDEX(_xlfn._xlws.FILTER('Dang ky_onl'!$L$6:$L$4000,'Dang ky_onl'!$B$6:$B$4000=$B11),2),"")} | AZ11: {=IFERROR(INDEX(_xlfn._xlws.FILTER('Dang ky_onl'!$M$6:$M$4000,'Dang ky_onl'!$B$6:$B$4000=$B11),2),"")} | BC11: =ROUND(MIN(AY11*0.3+BA11*0.3+BB11*0.4+AZ11,10),1) -> #VALUE!
A12: 6 | B12: 2005230678 | C12: Lê Thị Hà | D12: Vy | F12: 01/11/2005 | G12: 14DHTP07 | H12: Đào Thị Tuyết Mai | I12: =IF(AND(J12>=4,K12="Đủ"), "Đậu", "Không đậu") -> Không đậu | K12: =IF(AND(L12>=3,M12>=2),"Đủ","Không đủ") -> Không đủ | L12: =M12+N12-O12 -> 0 | M12: {=SUMPRODUCT(--(LEN(CHOOSE({1,2,3},P12,X12,AF12))>0))} -> 0 | N12: {=SUMPRODUCT(--(LEN(CHOOSE({1,2},AN12,AV12))>0))} -> 0 | O12: =(IF(P12<>"",P12=X12,0)) +(IF(P12<>"",P12=AF12,0)) +(IF(P12<>"",P12=AN12,0)) +(IF(P12<>"",P12=AV12,0)) +(IF(X12<>"",X12=AF12,0)) +(IF(X12<>"",X12=AN12,0)) +(IF(X12<>"",X12=AV12,0)) +(IF(AF12<>"",AF12=AN12,0)) +(IF(AF12<>"",AF12=AV12,0)) +(IF(AN12<>"",AN12=AV12,0)) -> 0 | P12: {=IFERROR(INDEX(_xlfn._xlws.FILTER('Dang ky_off'!$J$4:$J$4000,'Dang ky_off'!$B$4:$B$4000=$B12),1),"")} | Q12: {=IFERROR(INDEX(_xlfn._xlws.FILTER('Dang ky_off'!$H$4:$H$4000,'Dang ky_off'!$B$4:$B$4000=$B12),1),"")} | R12: trực tiếp (offline) | S12: {=IFERROR(INDEX(_xlfn._xlws.FILTER('Dang ky_off'!$L$4:$L$4000,'Dang ky_off'!$B$4:$B$4000=$B12),1),"")} | T12: {=IFERROR(INDEX(_xlfn._xlws.FILTER('Dang ky_off'!$M$4:$M$4000,'Dang ky_off'!$B$4:$B$4000=$B12),1),"")} | W12: =ROUND(MIN(S12*0.3+U12*0.3+V12*0.4+T12,10),1) -> #VALUE! | X12: {=IFERROR(INDEX(_xlfn._xlws.FILTER('Dang ky_off'!$J$4:$J$4000,'Dang ky_off'!$B$4:$B$4000=$B12),2),"")} | Y12: {=IFERROR(INDEX(_xlfn._xlws.FILTER('Dang ky_off'!$H$4:$H$4000,'Dang ky_off'!$B$4:$B$4000=$B12),2),"")} | Z12: trực tiếp (offline) | AA12: {=IFERROR(INDEX(_xlfn._xlws.FILTER('Dang ky_off'!$L$4:$L$4000,'Dang ky_off'!$B$4:$B$4000=$B12),2),"")} | AB12: {=IFERROR(INDEX(_xlfn._xlws.FILTER('Dang ky_off'!$M$4:$M$4000,'Dang ky_off'!$B$4:$B$4000=$B12),2),"")} | AE12: =ROUND(MIN(AA12*0.3+AC12*0.3+AD12*0.4+AB12,10),1) -> #VALUE! | AF12: {=IFERROR(INDEX(_xlfn._xlws.FILTER('Dang ky_off'!$J$4:$J$43,'Dang ky_off'!$B$4:$B$43=$B12),3),"")} | AG12: {=IFERROR(INDEX(_xlfn._xlws.FILTER('Dang ky_off'!$H$4:$H$43,'Dang ky_off'!$B$4:$B$43=$B12),3),"")} | AH12: trực tiếp (offline) | AI12: {=IFERROR(INDEX(_xlfn._xlws.FILTER('Dang ky_off'!$L$4:$L$43,'Dang ky_off'!$B$4:$B$43=$B12),3),"")} | AJ12: {=IFERROR(INDEX(_xlfn._xlws.FILTER('Dang ky_off'!$M$4:$M$43,'Dang ky_off'!$B$4:$B$43=$B12),3),"")} | AM12: =ROUND(MIN(AI12*0.3+AK12*0.3+AL12*0.4+AJ12,10),1) -> #VALUE! | AN12: {=IFERROR(INDEX(_xlfn._xlws.FILTER('Dang ky_onl'!$J$6:$J$4000,'Dang ky_onl'!$B$6:$B$4000=$B12),1),"")} | AO12: {=IFERROR(INDEX(_xlfn._xlws.FILTER('Dang ky_onl'!$H$6:$H$4000,'Dang ky_onl'!$B$6:$B$4000=$B12),1),"")} | AP12: trực tuyến (online) | AQ12: {=IFERROR(INDEX(_xlfn._xlws.FILTER('Dang ky_onl'!$L$6:$L$4000,'Dang ky_onl'!$B$6:$B$4000=$B12),1),"")} | AR12: {=IFERROR(INDEX(_xlfn._xlws.FILTER('Dang ky_onl'!$M$6:$M$4000,'Dang ky_onl'!$B$6:$B$4000=$B12),1),"")} | AU12: =ROUND(MIN(AQ12*0.3+AS12*0.3+AT12*0.4+AR12,10),1) -> #VALUE! | AV12: {=IFERROR(INDEX(_xlfn._xlws.FILTER('Dang ky_onl'!$J$6:$J$4000,'Dang ky_onl'!$B$6:$B$4000=$B12),2),"")} | AW12: {=IFERROR(INDEX(_xlfn._xlws.FILTER('Dang ky_onl'!$H$6:$H$4000,'Dang ky_onl'!$B$6:$B$4000=$B12),2),"")} | AX12: trực tuyến (online) | AY12: {=IFERROR(INDEX(_xlfn._xlws.FILTER('Dang ky_onl'!$L$6:$L$4000,'Dang ky_onl'!$B$6:$B$4000=$B12),2),"")} | AZ12: {=IFERROR(INDEX(_xlfn._xlws.FILTER('Dang ky_onl'!$M$6:$M$4000,'Dang ky_onl'!$B$6:$B$4000=$B12),2),"")} | BC12: =ROUND(MIN(AY12*0.3+BA12*0.3+BB12*0.4+AZ12,10),1) -> #VALUE!
A13: 7 | B13: 2005230670 | C13: Nguyễn Bảo Thúy | D13: Vy | F13: 22/06/2005 | G13: 14DHTP07 | H13: Đào Thị Tuyết Mai | I13: =IF(AND(J13>=4,K13="Đủ"), "Đậu", "Không đậu") -> Không đậu | K13: =IF(AND(L13>=3,M13>=2),"Đủ","Không đủ") -> Không đủ | L13: =M13+N13-O13 -> 0 | M13: {=SUMPRODUCT(--(LEN(CHOOSE({1,2,3},P13,X13,AF13))>0))} -> 0 | N13: {=SUMPRODUCT(--(LEN(CHOOSE({1,2},AN13,AV13))>0))} -> 0 | O13: =(IF(P13<>"",P13=X13,0)) +(IF(P13<>"",P13=AF13,0)) +(IF(P13<>"",P13=AN13,0)) +(IF(P13<>"",P13=AV13,0)) +(IF(X13<>"",X13=AF13,0)) +(IF(X13<>"",X13=AN13,0)) +(IF(X13<>"",X13=AV13,0)) +(IF(AF13<>"",AF13=AN13,0)) +(IF(AF13<>"",AF13=AV13,0)) +(IF(AN13<>"",AN13=AV13,0)) -> 0 | P13: {=IFERROR(INDEX(_xlfn._xlws.FILTER('Dang ky_off'!$J$4:$J$4000,'Dang ky_off'!$B$4:$B$4000=$B13),1),"")} | Q13: {=IFERROR(INDEX(_xlfn._xlws.FILTER('Dang ky_off'!$H$4:$H$4000,'Dang ky_off'!$B$4:$B$4000=$B13),1),"")} | R13: trực tiếp (offline) | S13: {=IFERROR(INDEX(_xlfn._xlws.FILTER('Dang ky_off'!$L$4:$L$4000,'Dang ky_off'!$B$4:$B$4000=$B13),1),"")} | T13: {=IFERROR(INDEX(_xlfn._xlws.FILTER('Dang ky_off'!$M$4:$M$4000,'Dang ky_off'!$B$4:$B$4000=$B13),1),"")} | W13: =ROUND(MIN(S13*0.3+U13*0.3+V13*0.4+T13,10),1) -> #VALUE! | X13: {=IFERROR(INDEX(_xlfn._xlws.FILTER('Dang ky_off'!$J$4:$J$4000,'Dang ky_off'!$B$4:$B$4000=$B13),2),"")} | Y13: {=IFERROR(INDEX(_xlfn._xlws.FILTER('Dang ky_off'!$H$4:$H$4000,'Dang ky_off'!$B$4:$B$4000=$B13),2),"")} | Z13: trực tiếp (offline) | AA13: {=IFERROR(INDEX(_xlfn._xlws.FILTER('Dang ky_off'!$L$4:$L$4000,'Dang ky_off'!$B$4:$B$4000=$B13),2),"")} | AB13: {=IFERROR(INDEX(_xlfn._xlws.FILTER('Dang ky_off'!$M$4:$M$4000,'Dang ky_off'!$B$4:$B$4000=$B13),2),"")} | AE13: =ROUND(MIN(AA13*0.3+AC13*0.3+AD13*0.4+AB13,10),1) -> #VALUE! | AF13: {=IFERROR(INDEX(_xlfn._xlws.FILTER('Dang ky_off'!$J$4:$J$43,'Dang ky_off'!$B$4:$B$43=$B13),3),"")} | AG13: {=IFERROR(INDEX(_xlfn._xlws.FILTER('Dang ky_off'!$H$4:$H$43,'Dang ky_off'!$B$4:$B$43=$B13),3),"")} | AH13: trực tiếp (offline) | AI13: {=IFERROR(INDEX(_xlfn._xlws.FILTER('Dang ky_off'!$L$4:$L$43,'Dang ky_off'!$B$4:$B$43=$B13),3),"")} | AJ13: {=IFERROR(INDEX(_xlfn._xlws.FILTER('Dang ky_off'!$M$4:$M$43,'Dang ky_off'!$B$4:$B$43=$B13),3),"")} | AM13: =ROUND(MIN(AI13*0.3+AK13*0.3+AL13*0.4+AJ13,10),1) -> #VALUE! | AN13: {=IFERROR(INDEX(_xlfn._xlws.FILTER('Dang ky_onl'!$J$6:$J$4000,'Dang ky_onl'!$B$6:$B$4000=$B13),1),"")} | AO13: {=IFERROR(INDEX(_xlfn._xlws.FILTER('Dang ky_onl'!$H$6:$H$4000,'Dang ky_onl'!$B$6:$B$4000=$B13),1),"")} | AP13: trực tuyến (online) | AQ13: {=IFERROR(INDEX(_xlfn._xlws.FILTER('Dang ky_onl'!$L$6:$L$4000,'Dang ky_onl'!$B$6:$B$4000=$B13),1),"")} | AR13: {=IFERROR(INDEX(_xlfn._xlws.FILTER('Dang ky_onl'!$M$6:$M$4000,'Dang ky_onl'!$B$6:$B$4000=$B13),1),"")} | AU13: =ROUND(MIN(AQ13*0.3+AS13*0.3+AT13*0.4+AR13,10),1) -> #VALUE! | AV13: {=IFERROR(INDEX(_xlfn._xlws.FILTER('Dang ky_onl'!$J$6:$J$4000,'Dang ky_onl'!$B$6:$B$4000=$B13),2),"")} | AW13: {=IFERROR(INDEX(_xlfn._xlws.FILTER('Dang ky_onl'!$H$6:$H$4000,'Dang ky_onl'!$B$6:$B$4000=$B13),2),"")} | AX13: trực tuyến (online) | AY13: {=IFERROR(INDEX(_xlfn._xlws.FILTER('Dang ky_onl'!$L$6:$L$4000,'Dang ky_onl'!$B$6:$B$4000=$B13),2),"")} | AZ13: {=IFERROR(INDEX(_xlfn._xlws.FILTER('Dang ky_onl'!$M$6:$M$4000,'Dang ky_onl'!$B$6:$B$4000=$B13),2),"")} | BC13: =ROUND(MIN(AY13*0.3+BA13*0.3+BB13*0.4+AZ13,10),1) -> #VALUE!
A14: 8 | B14: 2005230025 | C14: Nguyễn Thị Ngọc | D14: Anh | F14: 18/12/2005 | G14: 14DHTP08 | H14: Đào Thị Tuyết Mai | I14: =IF(AND(J14>=4,K14="Đủ"), "Đậu", "Không đậu") -> Không đậu | K14: =IF(AND(L14>=3,M14>=2),"Đủ","Không đủ") -> Không đủ | L14: =M14+N14-O14 -> 0 | M14: {=SUMPRODUCT(--(LEN(CHOOSE({1,2,3},P14,X14,AF14))>0))} -> 0 | N14: {=SUMPRODUCT(--(LEN(CHOOSE({1,2},AN14,AV14))>0))} -> 0 | O14: =(IF(P14<>"",P14=X14,0)) +(IF(P14<>"",P14=AF14,0)) +(IF(P14<>"",P14=AN14,0)) +(IF(P14<>"",P14=AV14,0)) +(IF(X14<>"",X14=AF14,0)) +(IF(X14<>"",X14=AN14,0)) +(IF(X14<>"",X14=AV14,0)) +(IF(AF14<>"",AF14=AN14,0)) +(IF(AF14<>"",AF14=AV14,0)) +(IF(AN14<>"",AN14=AV14,0)) -> 0 | P14: {=IFERROR(INDEX(_xlfn._xlws.FILTER('Dang ky_off'!$J$4:$J$4000,'Dang ky_off'!$B$4:$B$4000=$B14),1),"")} | Q14: {=IFERROR(INDEX(_xlfn._xlws.FILTER('Dang ky_off'!$H$4:$H$4000,'Dang ky_off'!$B$4:$B$4000=$B14),1),"")} | R14: trực tiếp (offline) | S14: {=IFERROR(INDEX(_xlfn._xlws.FILTER('Dang ky_off'!$L$4:$L$4000,'Dang ky_off'!$B$4:$B$4000=$B14),1),"")} | T14: {=IFERROR(INDEX(_xlfn._xlws.FILTER('Dang ky_off'!$M$4:$M$4000,'Dang ky_off'!$B$4:$B$4000=$B14),1),"")} | W14: =ROUND(MIN(S14*0.3+U14*0.3+V14*0.4+T14,10),1) -> #VALUE! | X14: {=IFERROR(INDEX(_xlfn._xlws.FILTER('Dang ky_off'!$J$4:$J$4000,'Dang ky_off'!$B$4:$B$4000=$B14),2),"")} | Y14: {=IFERROR(INDEX(_xlfn._xlws.FILTER('Dang ky_off'!$H$4:$H$4000,'Dang ky_off'!$B$4:$B$4000=$B14),2),"")} | Z14: trực tiếp (offline) | AA14: {=IFERROR(INDEX(_xlfn._xlws.FILTER('Dang ky_off'!$L$4:$L$4000,'Dang ky_off'!$B$4:$B$4000=$B14),2),"")} | AB14: {=IFERROR(INDEX(_xlfn._xlws.FILTER('Dang ky_off'!$M$4:$M$4000,'Dang ky_off'!$B$4:$B$4000=$B14),2),"")} | AE14: =ROUND(MIN(AA14*0.3+AC14*0.3+AD14*0.4+AB14,10),1) -> #VALUE! | AF14: {=IFERROR(INDEX(_xlfn._xlws.FILTER('Dang ky_off'!$J$4:$J$43,'Dang ky_off'!$B$4:$B$43=$B14),3),"")} | AG14: {=IFERROR(INDEX(_xlfn._xlws.FILTER('Dang ky_off'!$H$4:$H$43,'Dang ky_off'!$B$4:$B$43=$B14),3),"")} | AH14: trực tiếp (offline) | AI14: {=IFERROR(INDEX(_xlfn._xlws.FILTER('Dang ky_off'!$L$4:$L$43,'Dang ky_off'!$B$4:$B$43=$B14),3),"")} | AJ14: {=IFERROR(INDEX(_xlfn._xlws.FILTER('Dang ky_off'!$M$4:$M$43,'Dang ky_off'!$B$4:$B$43=$B14),3),"")} | AM14: =ROUND(MIN(AI14*0.3+AK14*0.3+AL14*0.4+AJ14,10),1) -> #VALUE! | AN14: {=IFERROR(INDEX(_xlfn._xlws.FILTER('Dang ky_onl'!$J$6:$J$4000,'Dang ky_onl'!$B$6:$B$4000=$B14),1),"")} | AO14: {=IFERROR(INDEX(_xlfn._xlws.FILTER('Dang ky_onl'!$H$6:$H$4000,'Dang ky_onl'!$B$6:$B$4000=$B14),1),"")} | AP14: trực tuyến (online) | AQ14: {=IFERROR(INDEX(_xlfn._xlws.FILTER('Dang ky_onl'!$L$6:$L$4000,'Dang ky_onl'!$B$6:$B$4000=$B14),1),"")} | AR14: {=IFERROR(INDEX(_xlfn._xlws.FILTER('Dang ky_onl'!$M$6:$M$4000,'Dang ky_onl'!$B$6:$B$4000=$B14),1),"")} | AU14: =ROUND(MIN(AQ14*0.3+AS14*0.3+AT14*0.4+AR14,10),1) -> #VALUE! | AV14: {=IFERROR(INDEX(_xlfn._xlws.FILTER('Dang ky_onl'!$J$6:$J$4000,'Dang ky_onl'!$B$6:$B$4000=$B14),2),"")} | AW14: {=IFERROR(INDEX(_xlfn._xlws.FILTER('Dang ky_onl'!$H$6:$H$4000,'Dang ky_onl'!$B$6:$B$4000=$B14),2),"")} | AX14: trực tuyến (online) | AY14: {=IFERROR(INDEX(_xlfn._xlws.FILTER('Dang ky_onl'!$L$6:$L$4000,'Dang ky_onl'!$B$6:$B$4000=$B14),2),"")} | AZ14: {=IFERROR(INDEX(_xlfn._xlws.FILTER('Dang ky_onl'!$M$6:$M$4000,'Dang ky_onl'!$B$6:$B$4000=$B14),2),"")} | BC14: =ROUND(MIN(AY14*0.3+BA14*0.3+BB14*0.4+AZ14,10),1) -> #VALUE!
